Workbook
Name _1__xlnm.Criteria: #REF!
Name _10__xlnm.Print_Area_13: #REF!
Name _11__xlnm.Print_Area_14: #REF!
Name _12__xlnm.Print_Area_15: #REF!
Name _13__xlnm.Print_Area_16: #REF!
Name _14__xlnm.Print_Area_2: #REF!
Name _15__xlnm.Print_Area_3: #REF!
Name _16__xlnm.Print_Area_4: #REF!
Name _17__xlnm.Print_Area_5: #REF!
Name _18__xlnm.Print_Area_6: #REF!
Name _19__xlnm.Print_Area_7: #REF!
Name _2__xlnm.Database: #REF!
Name _20__xlnm.Print_Area_8: #REF!
Name _21__xlnm.Print_Area_9: #REF!
Name _3__xlnm.Extract: #REF!
Name _4__xlnm.Print_Area: #REF!
Name _6__xlnm.Print_Area_1: #REF!
Name _7__xlnm.Print_Area_10: #REF!
Name _8__xlnm.Print_Area_11: #REF!
Name _9__xlnm.Print_Area_12: #REF!
Name DATOS: #REF!
Name L_Categorias: #REF!
Name L_GrupContenidos: #REF!
Name L_Macro: #REF!
Name L_Micros: #REF!
Name ListaLunes: _Lunes!$A$1:$A$366
Name M3_Competicion: #REF!
Name M3_Manteni: #REF!
Name M3_Preparatorio: #REF!
Name M3_TransDirigi: #REF!
Name M3_TransEspecial: #REF!
Name M4_Competicion: #REF!
Name M4_Manteni: #REF!
Name M4_Preparatorio: #REF!
Name M4_TransDirigi: #REF!
Name M4_TransEspecial: #REF!
Name M5_Competicion: #REF!
Name M5_Manteni: #REF!
Name M5_Preparatorio: #REF!
Name M5_TransDirigi: #REF!
Name M5_TransEspecial: #REF!
Name M6_Competicion: #REF!
Name M6_Manteni: #REF!
Name M6_Preparatorio: #REF!
Name M6_TransDirigi: #REF!
Name M6_TransEspecial: #REF!
Name M7_Competicion: #REF!
Name M7_Manteni: #REF!
Name M7_Preparatorio: #REF!
Name M7_TransDirigi: #REF!
Name M7_TransEspecial: #REF!
Name M7_TransManten: #REF!
Name MORPHOTYPE: #REF!
Name Plan_ConteMicro: #REF!
Name Plan_Contesesion: #REF!
Name Plan_Temp: #REF!
Name RangoModelMicro: INDIRECT(#REF!)
Name T_CargaOrientaEjercicio: #REF!
Name T_Cont1: OFFSET(#REF!,0,0,COUNTA(#REF!),3)
Name T_Cont2: OFFSET(#REF!,0,0,COUNTA(#REF!),3)

Sheet INPUT
A1: =HYPERLINK("#'INPUT'!A"&(COUNTA($A$3:$A$5000)+3),"▼ Siguiente fila vacía — TABLA 1 SESIONES") -> ▼ Siguiente fila vacía — TABLA 1 SESIONES | H1: =HYPERLINK("#'INPUT'!H"&(COUNTA($H$3:$H$5000)+3),"▼ Siguiente vacía — T2 BORG") -> ▼ Siguiente vacía — T2 BORG | M1: =HYPERLINK("#'INPUT'!M"&(COUNTA($M$3:$M$5000)+3),"▼ Siguiente vacía — T3 PESO") -> ▼ Siguiente vacía — T3 PESO | T1: =HYPERLINK("#'INPUT'!T"&(COUNTA($T$3:$T$5000)+3),"▼ Siguiente vacía — T4 WELLNESS") -> ▼ Siguiente vacía — T4 WELLNESS
A2: FECHA | B2: SEMANA | C2: TURNO | D2: TIPO SESIÓN | E2: MINUTOS | F2: COMPETICIÓN | H2: FECHA | I2: TURNO | J2: JUGADOR | K2: BORG | M2: FECHA | N2: TURNO | O2: JUGADOR | P2: PESO PRE | Q2: PESO POST | R2: H2O (L) | T2: FECHA | U2: JUGADOR | V2: SUEÑO | W2: FATIGA | X2: MOLESTIAS | Y2: ÁNIMO | Z2: TOTAL
A3: 45868 | B3: =IFERROR(_xlfn.ISOWEEKNUM(A3),"") -> 31 | C3: T | D3: FISICO | E3: 180 | F3: PRE-TEMPORADA | H3: 45868 | I3: T | J3: BARONA | K3: 7 | M3: 45868 | N3: T | O3: HERRERO | P3: 77 | Q3: 75.8 | R3: =IFERROR(P3-Q3,"") -> 1.2 | T3: 45868 | U3: HERRERO | V3: 2 | W3: 2 | X3: 1 | Y3: 3 | Z3: =SUM(V3:Y3) -> 8
A4: 45869 | B4: =IFERROR(_xlfn.ISOWEEKNUM(A4),"") -> 31 | C4: T | D4: FISICO | E4: 150 | F4: PRE-TEMPORADA | H4: 45868 | I4: T | J4: CARLOS | K4: 9 | M4: 45868 | N4: T | O4: GARCIA | P4: 78.6 | Q4: 78.5 | R4: =IFERROR(P4-Q4,"") -> 0.1 | T4: 45868 | U4: GARCIA | V4: 5 | W4: 5 | X4: 4 | Y4: 5 | Z4: =SUM(V4:Y4) -> 19
A5: 45870 | B5: =IFERROR(_xlfn.ISOWEEKNUM(A5),"") -> 31 | C5: T | D5: FISICO | E5: 180 | F5: PRE-TEMPORADA | H5: 45868 | I5: T | J5: CECILIO | K5: 8 | M5: 45868 | N5: T | O5: OSCAR | P5: 88.6 | Q5: 88.6 | R5: =IFERROR(P5-Q5,"") -> 0 | T5: 45868 | U5: OSCAR | V5: 5 | W5: 5 | X5: 5 | Y5: 5 | Z5: =SUM(V5:Y5) -> 20
A6: 45873 | B6: =IFERROR(_xlfn.ISOWEEKNUM(A6),"") -> 32 | C6: M | D6: GYM | E6: 75 | F6: PRE-TEMPORADA | H6: 45868 | I6: T | J6: CHAGUINHA | K6: 8 | M6: 45868 | N6: T | O6: CECILIO | P6: 68.1 | Q6: 67.9 | R6: =IFERROR(P6-Q6,"") -> 0.2 | T6: 45868 | U6: CECILIO | V6: 4 | W6: 4 | X6: 3 | Y6: 5 | Z6: =SUM(V6:Y6) -> 16
A7: 45873 | B7: =IFERROR(_xlfn.ISOWEEKNUM(A7),"") -> 32 | C7: T | D7: TEC-TAC | E7: 135 | F7: PRE-TEMPORADA | H7: 45868 | I7: T | J7: DANI | K7: 10 | M7: 45868 | N7: T | O7: CHAGUINHA | P7: 68.7 | Q7: 68 | R7: =IFERROR(P7-Q7,"") -> 0.7 | T7: 45868 | U7: CHAGUINHA | V7: 3 | W7: 4 | X7: 3 | Y7: 5 | Z7: =SUM(V7:Y7) -> 15
A8: 45874 | B8: =IFERROR(_xlfn.ISOWEEKNUM(A8),"") -> 32 | C8: M | D8: FISICO | E8: 150 | F8: PRE-TEMPORADA | H8: 45868 | I8: T | J8: GARCIA | K8: 8 | M8: 45868 | N8: T | O8: RAUL | P8: 79.8 | Q8: 79 | R8: =IFERROR(P8-Q8,"") -> 0.8 | T8: 45868 | U8: RAUL | V8: 5 | W8: 5 | X8: 5 | Y8: 5 | Z8: =SUM(V8:Y8) -> 20
A9: 45875 | B9: =IFERROR(_xlfn.ISOWEEKNUM(A9),"") -> 32 | C9: M | D9: TEC-TAC | E9: 120 | F9: PRE-TEMPORADA | H9: 45868 | I9: T | J9: GONZALO | K9: 8 | M9: 45868 | N9: T | O9: HARRISON | P9: 72.7 | Q9: 72.3 | R9: =IFERROR(P9-Q9,"") -> 0.4 | T9: 45868 | U9: HARRISON | V9: 4 | W9: 4 | X9: 5 | Y9: 5 | Z9: =SUM(V9:Y9) -> 18
A10: 45875 | B10: =IFERROR(_xlfn.ISOWEEKNUM(A10),"") -> 32 | C10: T | D10: TEC-TAC | E10: 120 | F10: PRE-TEMPORADA | H10: 45868 | I10: T | J10: HARRISON | K10: 9 | M10: 45868 | N10: T | O10: RAYA | P10: 82.9 | Q10: 81 | R10: =IFERROR(P10-Q10,"") -> 1.9 | T10: 45868 | U10: RAYA | V10: 4 | W10: 3 | X10: 3 | Y10: 5 | Z10: =SUM(V10:Y10) -> 15
A11: 45876 | B11: =IFERROR(_xlfn.ISOWEEKNUM(A11),"") -> 32 | C11: M | D11: GYM | E11: 70 | F11: PRE-TEMPORADA | H11: 45868 | I11: T | J11: HERRERO | K11: 10 | M11: 45868 | N11: T | O11: JAVI | P11: 78.3 | Q11: 77.1 | R11: =IFERROR(P11-Q11,"") -> 1.2 | T11: 45868 | U11: JAVI | V11: 4 | W11: 4 | X11: 4 | Y11: 4 | Z11: =SUM(V11:Y11) -> 16
A12: 45876 | B12: =IFERROR(_xlfn.ISOWEEKNUM(A12),"") -> 32 | C12: T | D12: TEC-TAC | E12: 120 | F12: PRE-TEMPORADA | H12: 45868 | I12: T | J12: JAIME | K12: 9 | M12: 45868 | N12: T | O12: PANI | P12: 70.6 | Q12: 70 | R12: =IFERROR(P12-Q12,"") -> 0.6 | T12: 45868 | U12: PANI | V12: 5 | W12: 5 | X12: 3 | Y12: 5 | Z12: =SUM(V12:Y12) -> 18
A13: 45877 | B13: =IFERROR(_xlfn.ISOWEEKNUM(A13),"") -> 32 | C13: M | D13: TEC-TAC | E13: 90 | F13: PRE-TEMPORADA | H13: 45868 | I13: T | J13: JAVI | K13: 9 | M13: 45868 | N13: T | O13: PIRATA | P13: 75.6 | Q13: 74.2 | R13: =IFERROR(P13-Q13,"") -> 1.4 | T13: 45868 | U13: PIRATA | V13: 5 | W13: 5 | X13: 5 | Y13: 5 | Z13: =SUM(V13:Y13) -> 20
A14: 45877 | B14: =IFERROR(_xlfn.ISOWEEKNUM(A14),"") -> 32 | C14: T | D14: PARTIDO | E14: 120 | F14: PRE-TEMPORADA | H14: 45868 | I14: T | J14: OSCAR | K14: 9 | M14: 45868 | N14: T | O14: BARONA | P14: 71.2 | Q14: 70.7 | R14: =IFERROR(P14-Q14,"") -> 0.5 | T14: 45868 | U14: BARONA | V14: 5 | W14: 5 | X14: 5 | Y14: 5 | Z14: =SUM(V14:Y14) -> 20
... A63: 45925 | B63: =IFERROR(_xlfn.ISOWEEKNUM(A63),"") -> 39 | C63: M | D63: TEC-TAC | E63: 90 | F63: PRE-TEMPORADA | H63: 45873 | I63: M | J63: JAIME | K63: 7 | M63: 45873 | N63: T | O63: PIRATA | P63: 76 | Q63: 76 | R63: =IFERROR(P63-Q63,"") -> 0 | T63: 45873 | U63: HARRISON | V63: 4 | W63: 5 | X63: 4 | Y63: 5 | Z63: =SUM(V63:Y63) -> 18
A64: 45926 | B64: =IFERROR(_xlfn.ISOWEEKNUM(A64),"") -> 39 | C64: M | D64: TEC-TAC | E64: 90 | F64: PRE-TEMPORADA | H64: 45873 | I64: M | J64: JAVI | K64: A | M64: 45873 | N64: T | O64: BARONA | P64: 71.3 | Q64: 71 | R64: =IFERROR(P64-Q64,"") -> 0.3 | T64: 45873 | U64: RAYA | V64: 5 | W64: 4 | X64: 3 | Y64: 5 | Z64: =SUM(V64:Y64) -> 17
A65: 45927 | B65: =IFERROR(_xlfn.ISOWEEKNUM(A65),"") -> 39 | C65: M | D65: PARTIDO | E65: 120 | F65: PRE-TEMPORADA | H65: 45873 | I65: M | J65: OSCAR | K65: 7 | M65: 45873 | N65: T | O65: CARLOS | P65: 67.7 | Q65: 67.1 | R65: =IFERROR(P65-Q65,"") -> 0.6 | T65: 45873 | U65: PANI | V65: 4 | W65: 4 | X65: 3 | Y65: 5 | Z65: =SUM(V65:Y65) -> 16
A66: 45929 | B66: =IFERROR(_xlfn.ISOWEEKNUM(A66),"") -> 40 | C66: M | D66: GYM | E66: 60 | F66: PRE-TEMPORADA | H66: 45873 | I66: M | J66: PANI | K66: 7 | M66: 45873 | N66: T | O66: GONZALO | P66: 85.2 | Q66: 85.1 | R66: =IFERROR(P66-Q66,"") -> 0.1 | T66: 45873 | U66: PIRATA | V66: 4 | W66: 5 | X66: 5 | Y66: 5 | Z66: =SUM(V66:Y66) -> 19
A67: 45929 | B67: =IFERROR(_xlfn.ISOWEEKNUM(A67),"") -> 40 | C67: T | D67: TEC-TAC | E67: 75 | F67: PRE-TEMPORADA | H67: 45873 | I67: M | J67: PIRATA | K67: 7 | M67: 45873 | N67: T | O67: RUBIO | P67: 75 | Q67: 74 | R67: =IFERROR(P67-Q67,"") -> 1 | T67: 45873 | U67: BARONA | V67: 3 | W67: 5 | X67: 3 | Y67: 5 | Z67: =SUM(V67:Y67) -> 16
A68: 45930 | B68: =IFERROR(_xlfn.ISOWEEKNUM(A68),"") -> 40 | C68: M | D68: TEC-TAC | E68: 105 | F68: PRE-TEMPORADA | H68: 45873 | I68: M | J68: RAUL | K68: 7 | M68: 45873 | N68: T | O68: DANI | P68: 93.8 | Q68: 93.1 | R68: =IFERROR(P68-Q68,"") -> 0.7 | T68: 45873 | U68: CARLOS | V68: 4 | W68: 4 | X68: 5 | Y68: 5 | Z68: =SUM(V68:Y68) -> 18
A69: 45931 | B69: =IFERROR(_xlfn.ISOWEEKNUM(A69),"") -> 40 | C69: M | D69: GYM | E69: 90 | F69: PRE-TEMPORADA | H69: 45873 | I69: M | J69: RAYA | K69: 7 | M69: 45873 | N69: T | O69: JAIME | P69: 75.4 | Q69: 75.2 | R69: =IFERROR(P69-Q69,"") -> 0.2 | T69: 45873 | U69: GONZALO | V69: 5 | W69: 5 | X69: 5 | Y69: 4 | Z69: =SUM(V69:Y69) -> 19
A70: 45931 | B70: =IFERROR(_xlfn.ISOWEEKNUM(A70),"") -> 40 | C70: T | D70: TEC-TAC | E70: 75 | F70: PRE-TEMPORADA | H70: 45873 | I70: M | J70: RUBIO | K70: 7 | M70: 45874 | N70: M | O70: HERRERO | P70: 76.9 | Q70: 75.3 | R70: =IFERROR(P70-Q70,"") -> 1.6 | T70: 45873 | U70: RUBIO | V70: 4 | W70: 4 | X70: 4 | Y70: 5 | Z70: =SUM(V70:Y70) -> 17
A71: 45932 | B71: =IFERROR(_xlfn.ISOWEEKNUM(A71),"") -> 40 | C71: M | D71: TEC-TAC | E71: 95 | F71: PRE-TEMPORADA | H71: 45873 | I71: T | J71: BARONA | K71: 8 | M71: 45874 | N71: M | O71: GARCIA | P71: 78.9 | Q71: 78 | R71: =IFERROR(P71-Q71,"") -> 0.9 | T71: 45873 | U71: DANI | V71: 4 | W71: 4 | X71: 5 | Y71: 5 | Z71: =SUM(V71:Y71) -> 18
A72: 45933 | B72: =IFERROR(_xlfn.ISOWEEKNUM(A72),"") -> 40 | C72: M | D72: TEC-TAC | E72: 75 | F72: PRE-TEMPORADA | H72: 45873 | I72: T | J72: CARLOS | K72: 6 | M72: 45874 | N72: M | O72: OSCAR | P72: 88.9 | Q72: 88.5 | R72: =IFERROR(P72-Q72,"") -> 0.4 | T72: 45873 | U72: JAIME | V72: 4 | W72: 4 | X72: 5 | Y72: 4 | Z72: =SUM(V72:Y72) -> 17
A73: 45934 | B73: =IFERROR(_xlfn.ISOWEEKNUM(A73),"") -> 40 | C73: M | D73: PARTIDO | E73: 120 | F73: PRE-TEMPORADA | H73: 45873 | I73: T | J73: CECILIO | K73: 6 | M73: 45874 | N73: M | O73: CECILIO | P73: 68.5 | Q73: 68.6 | R73: =IFERROR(P73-Q73,"") -> -0.1 | T73: 45873 | U73: MEDIA | V73: 4.125 | W73: 4.3125 | X73: 4.25 | Y73: 4.6875 | Z73: =SUM(V73:Y73) -> 17.375
A74: 45936 | B74: =IFERROR(_xlfn.ISOWEEKNUM(A74),"") -> 41 | C74: M | D74: TEC-TAC | E74: 95 | F74: PRE-TEMPORADA | H74: 45873 | I74: T | J74: CHAGUINHA | K74: 7 | M74: 45874 | N74: M | O74: CHAGUINHA | P74: 68.5 | Q74: 67.6 | R74: =IFERROR(P74-Q74,"") -> 0.9 | T74: 45874 | U74: HERRERO | V74: 2 | W74: 2 | X74: 2 | Y74: 2 | Z74: =SUM(V74:Y74) -> 8
A75: 45937 | B75: =IFERROR(_xlfn.ISOWEEKNUM(A75),"") -> 41 | C75: M | D75: TEC-TAC | E75: 75 | F75: PRE-TEMPORADA | H75: 45873 | I75: T | J75: DANI | K75: 6 | M75: 45874 | N75: M | O75: RAUL | P75: 79.2 | Q75: 78.8 | R75: =IFERROR(P75-Q75,"") -> 0.4 | T75: 45874 | U75: GARCIA | V75: 3 | W75: 4 | X75: 4 | Y75: 5 | Z75: =SUM(V75:Y75) -> 16
A76: 45938 | B76: =IFERROR(_xlfn.ISOWEEKNUM(A76),"") -> 41 | C76: M | D76: MATINAL | E76: 40 | F76: PRE-TEMPORADA | H76: 45873 | I76: T | J76: GARCIA | K76: 6 | M76: 45874 | N76: M | O76: HARRISON | P76: 71.8 | Q76: 72.1 | R76: =IFERROR(P76-Q76,"") -> -0.3 | T76: 45874 | U76: OSCAR | V76: 3 | W76: 5 | X76: 5 | Y76: 5 | Z76: =SUM(V76:Y76) -> 18
... A80: 45942 | B80: =IFERROR(_xlfn.ISOWEEKNUM(A80),"") -> 41 | C80: M | D80: PARTIDO | E80: 120 | F80: PRE-TEMPORADA | H80: 45873 | I80: T | J80: JAIME | K80: 9 | M80: 45874 | N80: M | O80: BARONA | P80: 70.6 | Q80: 70.3 | R80: =IFERROR(P80-Q80,"") -> 0.3 | T80: 45874 | U80: HARRISON | V80: 3 | W80: 3 | X80: 4 | Y80: 5 | Z80: =SUM(V80:Y80) -> 15
A81: 45944 | B81: =IFERROR(_xlfn.ISOWEEKNUM(A81),"") -> 42 | C81: M | D81: GYM+TEC-TAC | E81: 160 | F81: PRE-TEMPORADA | H81: 45873 | I81: T | J81: JAVI | K81: A | M81: 45874 | N81: M | O81: CARLOS | P81: 66.6 | Q81: 66.4 | R81: =IFERROR(P81-Q81,"") -> 0.2 | T81: 45874 | U81: RAYA | V81: 3 | W81: 4 | X81: 3 | Y81: 5 | Z81: =SUM(V81:Y81) -> 15
A82: 45945 | B82: =IFERROR(_xlfn.ISOWEEKNUM(A82),"") -> 42 | C82: T | D82: TEC-TAC | E82: 90 | F82: PRE-TEMPORADA | H82: 45873 | I82: T | J82: OSCAR | K82: 7 | M82: 45874 | N82: M | O82: GONZALO | P82: 85.1 | Q82: 84.7 | R82: =IFERROR(P82-Q82,"") -> 0.4 | T82: 45874 | U82: PANI | V82: 3 | W82: 3 | X82: 3 | Y82: 5 | Z82: =SUM(V82:Y82) -> 14
A83: 45946 | B83: =IFERROR(_xlfn.ISOWEEKNUM(A83),"") -> 42 | C83: M | D83: TEC-TAC | E83: 90 | F83: PRE-TEMPORADA | H83: 45873 | I83: T | J83: PANI | K83: 7 | M83: 45874 | N83: M | O83: RUBIO | P83: 74.4 | Q83: 74.2 | R83: =IFERROR(P83-Q83,"") -> 0.2 | T83: 45874 | U83: PIRATA | V83: 3 | W83: 3 | X83: 3 | Y83: 5 | Z83: =SUM(V83:Y83) -> 14
A84: 45947 | B84: =IFERROR(_xlfn.ISOWEEKNUM(A84),"") -> 42 | C84: M | D84: GYM+TEC-TAC | E84: 150 | F84: PRE-TEMPORADA | H84: 45873 | I84: T | J84: PIRATA | K84: 8 | M84: 45874 | N84: M | O84: DANI | P84: 93.5 | Q84: 92.6 | R84: =IFERROR(P84-Q84,"") -> 0.9 | T84: 45874 | U84: BARONA | V84: 4 | W84: 3 | X84: 2 | Y84: 5 | Z84: =SUM(V84:Y84) -> 14
A85: 45950 | B85: =IFERROR(_xlfn.ISOWEEKNUM(A85),"") -> 43 | C85: M | D85: GYM+TEC-TAC | E85: 90 | F85: PRE-TEMPORADA | H85: 45873 | I85: T | J85: RAUL | K85: 5 | M85: 45874 | N85: M | O85: JAIME | P85: 75.7 | Q85: 74.6 | R85: =IFERROR(P85-Q85,"") -> 1.1 | T85: 45874 | U85: CARLOS | V85: 3 | W85: 3 | X85: 5 | Y85: 5 | Z85: =SUM(V85:Y85) -> 16
A86: 45950 | B86: =IFERROR(_xlfn.ISOWEEKNUM(A86),"") -> 43 | C86: T | D86: TEC-TAC | E86: 90 | F86: PRE-TEMPORADA | H86: 45873 | I86: T | J86: RAYA | K86: 8 | M86: 45875 | N86: M | O86: HERRERO | P86: 77.3 | Q86: 76.5 | R86: =IFERROR(P86-Q86,"") -> 0.8 | T86: 45874 | U86: GONZALO | V86: 3 | W86: 3 | X86: 4 | Y86: 4 | Z86: =SUM(V86:Y86) -> 14
A87: 45951 | B87: =IFERROR(_xlfn.ISOWEEKNUM(A87),"") -> 43 | C87: M | D87: TEC-TAC | E87: 135 | F87: PRE-TEMPORADA | H87: 45873 | I87: T | J87: RUBIO | K87: 9 | M87: 45875 | N87: T | O87: HERRERO | P87: 77 | Q87: 76.6 | R87: =IFERROR(P87-Q87,"") -> 0.4 | T87: 45874 | U87: RUBIO | V87: 3 | W87: 4 | X87: 4 | Y87: 5 | Z87: =SUM(V87:Y87) -> 16
A88: 45952 | B88: =IFERROR(_xlfn.ISOWEEKNUM(A88),"") -> 43 | C88: M | D88: GYM+TEC-TAC | E88: 160 | F88: PRE-TEMPORADA | H88: 45874 | I88: M | J88: BARONA | K88: 8 | M88: 45875 | N88: M | O88: GARCIA | P88: 78.9 | Q88: 78.7 | R88: =IFERROR(P88-Q88,"") -> 0.2 | T88: 45874 | U88: DANI | V88: 3 | W88: 4 | X88: 5 | Y88: 4 | Z88: =SUM(V88:Y88) -> 16
A89: 45953 | B89: =IFERROR(_xlfn.ISOWEEKNUM(A89),"") -> 43 | C89: M | D89: TEC-TAC | E89: 110 | F89: PRE-TEMPORADA | H89: 45874 | I89: M | J89: CARLOS | K89: 9 | M89: 45875 | N89: T | O89: GARCIA | P89: 78.9 | Q89: 78.7 | R89: =IFERROR(P89-Q89,"") -> 0.2 | T89: 45874 | U89: JAIME | V89: 3 | W89: 4 | X89: 4 | Y89: 5 | Z89: =SUM(V89:Y89) -> 16
A90: 45954 | B90: =IFERROR(_xlfn.ISOWEEKNUM(A90),"") -> 43 | C90: T | D90: TEC-TAC | E90: 75 | F90: PRE-TEMPORADA | H90: 45874 | I90: M | J90: CECILIO | K90: 9 | M90: 45875 | N90: M | O90: OSCAR | P90: 91 | Q90: 89.7 | R90: =IFERROR(P90-Q90,"") -> 1.3 | T90: 45874 | U90: MEDIA | V90: 3.3125 | W90: 3.5625 | X90: 3.6875 | Y90: 4.6875 | Z90: =SUM(V90:Y90) -> 15.25
A91: 45955 | B91: =IFERROR(_xlfn.ISOWEEKNUM(A91),"") -> 43 | C91: T | D91: PARTIDO | E91: 120 | F91: PRE-TEMPORADA | H91: 45874 | I91: M | J91: CHAGUINHA | K91: 10 | M91: 45875 | N91: T | O91: OSCAR | P91: 89.9 | Q91: 89.9 | R91: =IFERROR(P91-Q91,"") -> 0 | T91: 45875 | U91: HERRERO | V91: 1 | W91: 2 | X91: 2 | Y91: 2 | Z91: =SUM(V91:Y91) -> 7
...

Sheet PESO SEMANA
A1: VISTA SEMANAL DE PESO
A2: Nº SEMANA → | B2: =IFERROR(_xlfn.ISOWEEKNUM(B3),"") -> 36 | C2: AÑO → | D2: =IFERROR(YEAR(B3),"") -> 2025 | E2: 💡 Selecciona el LUNES en B3 desde la lista desplegable · El nº de semana y el año se actualizan automáticamente · Los datos se leen de la hoja INPUT
A3: LUNES → | B3: 45901
D4: ="LUNES "&TEXT($B$3+0,"dd-mm-yyyy") -> LUNES 01-09-yyyy | G4: ="MARTES "&TEXT($B$3+1,"dd-mm-yyyy") -> MARTES 02-09-yyyy | J4: ="MIÉRCOLES "&TEXT($B$3+2,"dd-mm-yyyy") -> MIÉRCOLES 03-09-yyyy | M4: ="JUEVES "&TEXT($B$3+3,"dd-mm-yyyy") -> JUEVES 04-09-yyyy | P4: ="VIERNES "&TEXT($B$3+4,"dd-mm-yyyy") -> VIERNES 05-09-yyyy | S4: ="SÁBADO "&TEXT($B$3+5,"dd-mm-yyyy") -> SÁBADO 06-09-yyyy | V4: ="DOMINGO "&TEXT($B$3+6,"dd-mm-yyyy") -> DOMINGO 07-09-yyyy
A5: Nº | B5: JUGADOR | C5: TURNO | D5: PRE | E5: POST | F5: DIF | G5: PRE | H5: POST | I5: DIF | J5: PRE | K5: POST | L5: DIF | M5: PRE | N5: POST | O5: DIF | P5: PRE | Q5: POST | R5: DIF | S5: PRE | T5: POST | U5: DIF | V5: PRE | W5: POST | X5: DIF
A6: 1 | B6: HERRERO | C6: M | D6: {=IFERROR(IF(SUMPRODUCT((INPUT!$M$3:$M$1000=$B$3+0)*(INPUT!$N$3:$N$1000="M")*(INPUT!$O$3:$O$1000="HERRERO"))=0,"",SUMPRODUCT((INPUT!$M$3:$M$1000=$B$3+0)*(INPUT!$N$3:$N$1000="M")*(INPUT!$O$3:$O$1000="HERRERO")*INPUT!$P$3:$P$1000)),"")} | E6: {=IFERROR(IF(SUMPRODUCT((INPUT!$M$3:$M$1000=$B$3+0)*(INPUT!$N$3:$N$1000="M")*(INPUT!$O$3:$O$1000="HERRERO"))=0,"",SUMPRODUCT((INPUT!$M$3:$M$1000=$B$3+0)*(INPUT!$N$3:$N$1000="M")*(INPUT!$O$3:$O$1000="HERRERO")*INPUT!$Q$3:$Q$1000)),"")} | F6: =IFERROR(IF(OR(D6="",E6=""),"",D6-E6),"") | G6: {=IFERROR(IF(SUMPRODUCT((INPUT!$M$3:$M$1000=$B$3+1)*(INPUT!$N$3:$N$1000="M")*(INPUT!$O$3:$O$1000="HERRERO"))=0,"",SUMPRODUCT((INPUT!$M$3:$M$1000=$B$3+1)*(INPUT!$N$3:$N$1000="M")*(INPUT!$O$3:$O$1000="HERRERO")*INPUT!$P$3:$P$1000)),"")} -> 76.8 | H6: {=IFERROR(IF(SUMPRODUCT((INPUT!$M$3:$M$1000=$B$3+1)*(INPUT!$N$3:$N$1000="M")*(INPUT!$O$3:$O$1000="HERRERO"))=0,"",SUMPRODUCT((INPUT!$M$3:$M$1000=$B$3+1)*(INPUT!$N$3:$N$1000="M")*(INPUT!$O$3:$O$1000="HERRERO")*INPUT!$Q$3:$Q$1000)),"")} -> 76 | I6: =IFERROR(IF(OR(G6="",H6=""),"",G6-H6),"") -> 0.8 | J6: {=IFERROR(IF(SUMPRODUCT((INPUT!$M$3:$M$1000=$B$3+2)*(INPUT!$N$3:$N$1000="M")*(INPUT!$O$3:$O$1000="HERRERO"))=0,"",SUMPRODUCT((INPUT!$M$3:$M$1000=$B$3+2)*(INPUT!$N$3:$N$1000="M")*(INPUT!$O$3:$O$1000="HERRERO")*INPUT!$P$3:$P$1000)),"")} -> 76.8 | K6: {=IFERROR(IF(SUMPRODUCT((INPUT!$M$3:$M$1000=$B$3+2)*(INPUT!$N$3:$N$1000="M")*(INPUT!$O$3:$O$1000="HERRERO"))=0,"",SUMPRODUCT((INPUT!$M$3:$M$1000=$B$3+2)*(INPUT!$N$3:$N$1000="M")*(INPUT!$O$3:$O$1000="HERRERO")*INPUT!$Q$3:$Q$1000)),"")} -> 76 | L6: =IFERROR(IF(OR(J6="",K6=""),"",J6-K6),"") -> 0.8 | M6: {=IFERROR(IF(SUMPRODUCT((INPUT!$M$3:$M$1000=$B$3+3)*(INPUT!$N$3:$N$1000="M")*(INPUT!$O$3:$O$1000="HERRERO"))=0,"",SUMPRODUCT((INPUT!$M$3:$M$1000=$B$3+3)*(INPUT!$N$3:$N$1000="M")*(INPUT!$O$3:$O$1000="HERRERO")*INPUT!$P$3:$P$1000)),"")} -> 76.8 | N6: {=IFERROR(IF(SUMPRODUCT((INPUT!$M$3:$M$1000=$B$3+3)*(INPUT!$N$3:$N$1000="M")*(INPUT!$O$3:$O$1000="HERRERO"))=0,"",SUMPRODUCT((INPUT!$M$3:$M$1000=$B$3+3)*(INPUT!$N$3:$N$1000="M")*(INPUT!$O$3:$O$1000="HERRERO")*INPUT!$Q$3:$Q$1000)),"")} -> 76 | O6: =IFERROR(IF(OR(M6="",N6=""),"",M6-N6),"") -> 0.8 | P6: {=IFERROR(IF(SUMPRODUCT((INPUT!$M$3:$M$1000=$B$3+4)*(INPUT!$N$3:$N$1000="M")*(INPUT!$O$3:$O$1000="HERRERO"))=0,"",SUMPRODUCT((INPUT!$M$3:$M$1000=$B$3+4)*(INPUT!$N$3:$N$1000="M")*(INPUT!$O$3:$O$1000="HERRERO")*INPUT!$P$3:$P$1000)),"")} -> 76.8 | Q6: {=IFERROR(IF(SUMPRODUCT((INPUT!$M$3:$M$1000=$B$3+4)*(INPUT!$N$3:$N$1000="M")*(INPUT!$O$3:$O$1000="HERRERO"))=0,"",SUMPRODUCT((INPUT!$M$3:$M$1000=$B$3+4)*(INPUT!$N$3:$N$1000="M")*(INPUT!$O$3:$O$1000="HERRERO")*INPUT!$Q$3:$Q$1000)),"")} -> 76 | R6: =IFERROR(IF(OR(P6="",Q6=""),"",P6-Q6),"") -> 0.8 | S6: {=IFERROR(IF(SUMPRODUCT((INPUT!$M$3:$M$1000=$B$3+5)*(INPUT!$N$3:$N$1000="M")*(INPUT!$O$3:$O$1000="HERRERO"))=0,"",SUMPRODUCT((INPUT!$M$3:$M$1000=$B$3+5)*(INPUT!$N$3:$N$1000="M")*(INPUT!$O$3:$O$1000="HERRERO")*INPUT!$P$3:$P$1000)),"")} | T6: {=IFERROR(IF(SUMPRODUCT((INPUT!$M$3:$M$1000=$B$3+5)*(INPUT!$N$3:$N$1000="M")*(INPUT!$O$3:$O$1000="HERRERO"))=0,"",SUMPRODUCT((INPUT!$M$3:$M$1000=$B$3+5)*(INPUT!$N$3:$N$1000="M")*(INPUT!$O$3:$O$1000="HERRERO")*INPUT!$Q$3:$Q$1000)),"")} | U6: =IFERROR(IF(OR(S6="",T6=""),"",S6-T6),"") | V6: {=IFERROR(IF(SUMPRODUCT((INPUT!$M$3:$M$1000=$B$3+6)*(INPUT!$N$3:$N$1000="M")*(INPUT!$O$3:$O$1000="HERRERO"))=0,"",SUMPRODUCT((INPUT!$M$3:$M$1000=$B$3+6)*(INPUT!$N$3:$N$1000="M")*(INPUT!$O$3:$O$1000="HERRERO")*INPUT!$P$3:$P$1000)),"")} | W6: {=IFERROR(IF(SUMPRODUCT((INPUT!$M$3:$M$1000=$B$3+6)*(INPUT!$N$3:$N$1000="M")*(INPUT!$O$3:$O$1000="HERRERO"))=0,"",SUMPRODUCT((INPUT!$M$3:$M$1000=$B$3+6)*(INPUT!$N$3:$N$1000="M")*(INPUT!$O$3:$O$1000="HERRERO")*INPUT!$Q$3:$Q$1000)),"")} | X6: =IFERROR(IF(OR(V6="",W6=""),"",V6-W6),"")
C7: T | D7: {=IFERROR(IF(SUMPRODUCT((INPUT!$M$3:$M$1000=$B$3+0)*(INPUT!$N$3:$N$1000="T")*(INPUT!$O$3:$O$1000="HERRERO"))=0,"",SUMPRODUCT((INPUT!$M$3:$M$1000=$B$3+0)*(INPUT!$N$3:$N$1000="T")*(INPUT!$O$3:$O$1000="HERRERO")*INPUT!$P$3:$P$1000)),"")} | E7: {=IFERROR(IF(SUMPRODUCT((INPUT!$M$3:$M$1000=$B$3+0)*(INPUT!$N$3:$N$1000="T")*(INPUT!$O$3:$O$1000="HERRERO"))=0,"",SUMPRODUCT((INPUT!$M$3:$M$1000=$B$3+0)*(INPUT!$N$3:$N$1000="T")*(INPUT!$O$3:$O$1000="HERRERO")*INPUT!$Q$3:$Q$1000)),"")} | F7: =IFERROR(IF(OR(D7="",E7=""),"",D7-E7),"") | G7: {=IFERROR(IF(SUMPRODUCT((INPUT!$M$3:$M$1000=$B$3+1)*(INPUT!$N$3:$N$1000="T")*(INPUT!$O$3:$O$1000="HERRERO"))=0,"",SUMPRODUCT((INPUT!$M$3:$M$1000=$B$3+1)*(INPUT!$N$3:$N$1000="T")*(INPUT!$O$3:$O$1000="HERRERO")*INPUT!$P$3:$P$1000)),"")} | H7: {=IFERROR(IF(SUMPRODUCT((INPUT!$M$3:$M$1000=$B$3+1)*(INPUT!$N$3:$N$1000="T")*(INPUT!$O$3:$O$1000="HERRERO"))=0,"",SUMPRODUCT((INPUT!$M$3:$M$1000=$B$3+1)*(INPUT!$N$3:$N$1000="T")*(INPUT!$O$3:$O$1000="HERRERO")*INPUT!$Q$3:$Q$1000)),"")} | I7: =IFERROR(IF(OR(G7="",H7=""),"",G7-H7),"") | J7: {=IFERROR(IF(SUMPRODUCT((INPUT!$M$3:$M$1000=$B$3+2)*(INPUT!$N$3:$N$1000="T")*(INPUT!$O$3:$O$1000="HERRERO"))=0,"",SUMPRODUCT((INPUT!$M$3:$M$1000=$B$3+2)*(INPUT!$N$3:$N$1000="T")*(INPUT!$O$3:$O$1000="HERRERO")*INPUT!$P$3:$P$1000)),"")} | K7: {=IFERROR(IF(SUMPRODUCT((INPUT!$M$3:$M$1000=$B$3+2)*(INPUT!$N$3:$N$1000="T")*(INPUT!$O$3:$O$1000="HERRERO"))=0,"",SUMPRODUCT((INPUT!$M$3:$M$1000=$B$3+2)*(INPUT!$N$3:$N$1000="T")*(INPUT!$O$3:$O$1000="HERRERO")*INPUT!$Q$3:$Q$1000)),"")} | L7: =IFERROR(IF(OR(J7="",K7=""),"",J7-K7),"") | M7: {=IFERROR(IF(SUMPRODUCT((INPUT!$M$3:$M$1000=$B$3+3)*(INPUT!$N$3:$N$1000="T")*(INPUT!$O$3:$O$1000="HERRERO"))=0,"",SUMPRODUCT((INPUT!$M$3:$M$1000=$B$3+3)*(INPUT!$N$3:$N$1000="T")*(INPUT!$O$3:$O$1000="HERRERO")*INPUT!$P$3:$P$1000)),"")} | N7: {=IFERROR(IF(SUMPRODUCT((INPUT!$M$3:$M$1000=$B$3+3)*(INPUT!$N$3:$N$1000="T")*(INPUT!$O$3:$O$1000="HERRERO"))=0,"",SUMPRODUCT((INPUT!$M$3:$M$1000=$B$3+3)*(INPUT!$N$3:$N$1000="T")*(INPUT!$O$3:$O$1000="HERRERO")*INPUT!$Q$3:$Q$1000)),"")} | O7: =IFERROR(IF(OR(M7="",N7=""),"",M7-N7),"") | P7: {=IFERROR(IF(SUMPRODUCT((INPUT!$M$3:$M$1000=$B$3+4)*(INPUT!$N$3:$N$1000="T")*(INPUT!$O$3:$O$1000="HERRERO"))=0,"",SUMPRODUCT((INPUT!$M$3:$M$1000=$B$3+4)*(INPUT!$N$3:$N$1000="T")*(INPUT!$O$3:$O$1000="HERRERO")*INPUT!$P$3:$P$1000)),"")} | Q7: {=IFERROR(IF(SUMPRODUCT((INPUT!$M$3:$M$1000=$B$3+4)*(INPUT!$N$3:$N$1000="T")*(INPUT!$O$3:$O$1000="HERRERO"))=0,"",SUMPRODUCT((INPUT!$M$3:$M$1000=$B$3+4)*(INPUT!$N$3:$N$1000="T")*(INPUT!$O$3:$O$1000="HERRERO")*INPUT!$Q$3:$Q$1000)),"")} | R7: =IFERROR(IF(OR(P7="",Q7=""),"",P7-Q7),"") | S7: {=IFERROR(IF(SUMPRODUCT((INPUT!$M$3:$M$1000=$B$3+5)*(INPUT!$N$3:$N$1000="T")*(INPUT!$O$3:$O$1000="HERRERO"))=0,"",SUMPRODUCT((INPUT!$M$3:$M$1000=$B$3+5)*(INPUT!$N$3:$N$1000="T")*(INPUT!$O$3:$O$1000="HERRERO")*INPUT!$P$3:$P$1000)),"")} -> 77 | T7: {=IFERROR(IF(SUMPRODUCT((INPUT!$M$3:$M$1000=$B$3+5)*(INPUT!$N$3:$N$1000="T")*(INPUT!$O$3:$O$1000="HERRERO"))=0,"",SUMPRODUCT((INPUT!$M$3:$M$1000=$B$3+5)*(INPUT!$N$3:$N$1000="T")*(INPUT!$O$3:$O$1000="HERRERO")*INPUT!$Q$3:$Q$1000)),"")} -> 75.5 | U7: =IFERROR(IF(OR(S7="",T7=""),"",S7-T7),"") -> 1.5 | V7: {=IFERROR(IF(SUMPRODUCT((INPUT!$M$3:$M$1000=$B$3+6)*(INPUT!$N$3:$N$1000="T")*(INPUT!$O$3:$O$1000="HERRERO"))=0,"",SUMPRODUCT((INPUT!$M$3:$M$1000=$B$3+6)*(INPUT!$N$3:$N$1000="T")*(INPUT!$O$3:$O$1000="HERRERO")*INPUT!$P$3:$P$1000)),"")} | W7: {=IFERROR(IF(SUMPRODUCT((INPUT!$M$3:$M$1000=$B$3+6)*(INPUT!$N$3:$N$1000="T")*(INPUT!$O$3:$O$1000="HERRERO"))=0,"",SUMPRODUCT((INPUT!$M$3:$M$1000=$B$3+6)*(INPUT!$N$3:$N$1000="T")*(INPUT!$O$3:$O$1000="HERRERO")*INPUT!$Q$3:$Q$1000)),"")} | X7: =IFERROR(IF(OR(V7="",W7=""),"",V7-W7),"")
A8: 2 | B8: GARCIA | C8: M | D8: {=IFERROR(IF(SUMPRODUCT((INPUT!$M$3:$M$1000=$B$3+0)*(INPUT!$N$3:$N$1000="M")*(INPUT!$O$3:$O$1000="GARCIA"))=0,"",SUMPRODUCT((INPUT!$M$3:$M$1000=$B$3+0)*(INPUT!$N$3:$N$1000="M")*(INPUT!$O$3:$O$1000="GARCIA")*INPUT!$P$3:$P$1000)),"")} | E8: {=IFERROR(IF(SUMPRODUCT((INPUT!$M$3:$M$1000=$B$3+0)*(INPUT!$N$3:$N$1000="M")*(INPUT!$O$3:$O$1000="GARCIA"))=0,"",SUMPRODUCT((INPUT!$M$3:$M$1000=$B$3+0)*(INPUT!$N$3:$N$1000="M")*(INPUT!$O$3:$O$1000="GARCIA")*INPUT!$Q$3:$Q$1000)),"")} | F8: =IFERROR(IF(OR(D8="",E8=""),"",D8-E8),"") | G8: {=IFERROR(IF(SUMPRODUCT((INPUT!$M$3:$M$1000=$B$3+1)*(INPUT!$N$3:$N$1000="M")*(INPUT!$O$3:$O$1000="GARCIA"))=0,"",SUMPRODUCT((INPUT!$M$3:$M$1000=$B$3+1)*(INPUT!$N$3:$N$1000="M")*(INPUT!$O$3:$O$1000="GARCIA")*INPUT!$P$3:$P$1000)),"")} -> 79 | H8: {=IFERROR(IF(SUMPRODUCT((INPUT!$M$3:$M$1000=$B$3+1)*(INPUT!$N$3:$N$1000="M")*(INPUT!$O$3:$O$1000="GARCIA"))=0,"",SUMPRODUCT((INPUT!$M$3:$M$1000=$B$3+1)*(INPUT!$N$3:$N$1000="M")*(INPUT!$O$3:$O$1000="GARCIA")*INPUT!$Q$3:$Q$1000)),"")} -> 78.8 | I8: =IFERROR(IF(OR(G8="",H8=""),"",G8-H8),"") -> 0.2 | J8: {=IFERROR(IF(SUMPRODUCT((INPUT!$M$3:$M$1000=$B$3+2)*(INPUT!$N$3:$N$1000="M")*(INPUT!$O$3:$O$1000="GARCIA"))=0,"",SUMPRODUCT((INPUT!$M$3:$M$1000=$B$3+2)*(INPUT!$N$3:$N$1000="M")*(INPUT!$O$3:$O$1000="GARCIA")*INPUT!$P$3:$P$1000)),"")} -> 79.6 | K8: {=IFERROR(IF(SUMPRODUCT((INPUT!$M$3:$M$1000=$B$3+2)*(INPUT!$N$3:$N$1000="M")*(INPUT!$O$3:$O$1000="GARCIA"))=0,"",SUMPRODUCT((INPUT!$M$3:$M$1000=$B$3+2)*(INPUT!$N$3:$N$1000="M")*(INPUT!$O$3:$O$1000="GARCIA")*INPUT!$Q$3:$Q$1000)),"")} -> 79 | L8: =IFERROR(IF(OR(J8="",K8=""),"",J8-K8),"") -> 0.6 | M8: {=IFERROR(IF(SUMPRODUCT((INPUT!$M$3:$M$1000=$B$3+3)*(INPUT!$N$3:$N$1000="M")*(INPUT!$O$3:$O$1000="GARCIA"))=0,"",SUMPRODUCT((INPUT!$M$3:$M$1000=$B$3+3)*(INPUT!$N$3:$N$1000="M")*(INPUT!$O$3:$O$1000="GARCIA")*INPUT!$P$3:$P$1000)),"")} -> 79.6 | N8: {=IFERROR(IF(SUMPRODUCT((INPUT!$M$3:$M$1000=$B$3+3)*(INPUT!$N$3:$N$1000="M")*(INPUT!$O$3:$O$1000="GARCIA"))=0,"",SUMPRODUCT((INPUT!$M$3:$M$1000=$B$3+3)*(INPUT!$N$3:$N$1000="M")*(INPUT!$O$3:$O$1000="GARCIA")*INPUT!$Q$3:$Q$1000)),"")} -> 79 | O8: =IFERROR(IF(OR(M8="",N8=""),"",M8-N8),"") -> 0.6 | P8: {=IFERROR(IF(SUMPRODUCT((INPUT!$M$3:$M$1000=$B$3+4)*(INPUT!$N$3:$N$1000="M")*(INPUT!$O$3:$O$1000="GARCIA"))=0,"",SUMPRODUCT((INPUT!$M$3:$M$1000=$B$3+4)*(INPUT!$N$3:$N$1000="M")*(INPUT!$O$3:$O$1000="GARCIA")*INPUT!$P$3:$P$1000)),"")} -> 79.4 | Q8: {=IFERROR(IF(SUMPRODUCT((INPUT!$M$3:$M$1000=$B$3+4)*(INPUT!$N$3:$N$1000="M")*(INPUT!$O$3:$O$1000="GARCIA"))=0,"",SUMPRODUCT((INPUT!$M$3:$M$1000=$B$3+4)*(INPUT!$N$3:$N$1000="M")*(INPUT!$O$3:$O$1000="GARCIA")*INPUT!$Q$3:$Q$1000)),"")} -> 79 | R8: =IFERROR(IF(OR(P8="",Q8=""),"",P8-Q8),"") -> 0.4 | S8: {=IFERROR(IF(SUMPRODUCT((INPUT!$M$3:$M$1000=$B$3+5)*(INPUT!$N$3:$N$1000="M")*(INPUT!$O$3:$O$1000="GARCIA"))=0,"",SUMPRODUCT((INPUT!$M$3:$M$1000=$B$3+5)*(INPUT!$N$3:$N$1000="M")*(INPUT!$O$3:$O$1000="GARCIA")*INPUT!$P$3:$P$1000)),"")} | T8: {=IFERROR(IF(SUMPRODUCT((INPUT!$M$3:$M$1000=$B$3+5)*(INPUT!$N$3:$N$1000="M")*(INPUT!$O$3:$O$1000="GARCIA"))=0,"",SUMPRODUCT((INPUT!$M$3:$M$1000=$B$3+5)*(INPUT!$N$3:$N$1000="M")*(INPUT!$O$3:$O$1000="GARCIA")*INPUT!$Q$3:$Q$1000)),"")} | U8: =IFERROR(IF(OR(S8="",T8=""),"",S8-T8),"") | V8: {=IFERROR(IF(SUMPRODUCT((INPUT!$M$3:$M$1000=$B$3+6)*(INPUT!$N$3:$N$1000="M")*(INPUT!$O$3:$O$1000="GARCIA"))=0,"",SUMPRODUCT((INPUT!$M$3:$M$1000=$B$3+6)*(INPUT!$N$3:$N$1000="M")*(INPUT!$O$3:$O$1000="GARCIA")*INPUT!$P$3:$P$1000)),"")} | W8: {=IFERROR(IF(SUMPRODUCT((INPUT!$M$3:$M$1000=$B$3+6)*(INPUT!$N$3:$N$1000="M")*(INPUT!$O$3:$O$1000="GARCIA"))=0,"",SUMPRODUCT((INPUT!$M$3:$M$1000=$B$3+6)*(INPUT!$N$3:$N$1000="M")*(INPUT!$O$3:$O$1000="GARCIA")*INPUT!$Q$3:$Q$1000)),"")} | X8: =IFERROR(IF(OR(V8="",W8=""),"",V8-W8),"")
C9: T | D9: {=IFERROR(IF(SUMPRODUCT((INPUT!$M$3:$M$1000=$B$3+0)*(INPUT!$N$3:$N$1000="T")*(INPUT!$O$3:$O$1000="GARCIA"))=0,"",SUMPRODUCT((INPUT!$M$3:$M$1000=$B$3+0)*(INPUT!$N$3:$N$1000="T")*(INPUT!$O$3:$O$1000="GARCIA")*INPUT!$P$3:$P$1000)),"")} | E9: {=IFERROR(IF(SUMPRODUCT((INPUT!$M$3:$M$1000=$B$3+0)*(INPUT!$N$3:$N$1000="T")*(INPUT!$O$3:$O$1000="GARCIA"))=0,"",SUMPRODUCT((INPUT!$M$3:$M$1000=$B$3+0)*(INPUT!$N$3:$N$1000="T")*(INPUT!$O$3:$O$1000="GARCIA")*INPUT!$Q$3:$Q$1000)),"")} | F9: =IFERROR(IF(OR(D9="",E9=""),"",D9-E9),"") | G9: {=IFERROR(IF(SUMPRODUCT((INPUT!$M$3:$M$1000=$B$3+1)*(INPUT!$N$3:$N$1000="T")*(INPUT!$O$3:$O$1000="GARCIA"))=0,"",SUMPRODUCT((INPUT!$M$3:$M$1000=$B$3+1)*(INPUT!$N$3:$N$1000="T")*(INPUT!$O$3:$O$1000="GARCIA")*INPUT!$P$3:$P$1000)),"")} | H9: {=IFERROR(IF(SUMPRODUCT((INPUT!$M$3:$M$1000=$B$3+1)*(INPUT!$N$3:$N$1000="T")*(INPUT!$O$3:$O$1000="GARCIA"))=0,"",SUMPRODUCT((INPUT!$M$3:$M$1000=$B$3+1)*(INPUT!$N$3:$N$1000="T")*(INPUT!$O$3:$O$1000="GARCIA")*INPUT!$Q$3:$Q$1000)),"")} | I9: =IFERROR(IF(OR(G9="",H9=""),"",G9-H9),"") | J9: {=IFERROR(IF(SUMPRODUCT((INPUT!$M$3:$M$1000=$B$3+2)*(INPUT!$N$3:$N$1000="T")*(INPUT!$O$3:$O$1000="GARCIA"))=0,"",SUMPRODUCT((INPUT!$M$3:$M$1000=$B$3+2)*(INPUT!$N$3:$N$1000="T")*(INPUT!$O$3:$O$1000="GARCIA")*INPUT!$P$3:$P$1000)),"")} | K9: {=IFERROR(IF(SUMPRODUCT((INPUT!$M$3:$M$1000=$B$3+2)*(INPUT!$N$3:$N$1000="T")*(INPUT!$O$3:$O$1000="GARCIA"))=0,"",SUMPRODUCT((INPUT!$M$3:$M$1000=$B$3+2)*(INPUT!$N$3:$N$1000="T")*(INPUT!$O$3:$O$1000="GARCIA")*INPUT!$Q$3:$Q$1000)),"")} | L9: =IFERROR(IF(OR(J9="",K9=""),"",J9-K9),"") | M9: {=IFERROR(IF(SUMPRODUCT((INPUT!$M$3:$M$1000=$B$3+3)*(INPUT!$N$3:$N$1000="T")*(INPUT!$O$3:$O$1000="GARCIA"))=0,"",SUMPRODUCT((INPUT!$M$3:$M$1000=$B$3+3)*(INPUT!$N$3:$N$1000="T")*(INPUT!$O$3:$O$1000="GARCIA")*INPUT!$P$3:$P$1000)),"")} | N9: {=IFERROR(IF(SUMPRODUCT((INPUT!$M$3:$M$1000=$B$3+3)*(INPUT!$N$3:$N$1000="T")*(INPUT!$O$3:$O$1000="GARCIA"))=0,"",SUMPRODUCT((INPUT!$M$3:$M$1000=$B$3+3)*(INPUT!$N$3:$N$1000="T")*(INPUT!$O$3:$O$1000="GARCIA")*INPUT!$Q$3:$Q$1000)),"")} | O9: =IFERROR(IF(OR(M9="",N9=""),"",M9-N9),"") | P9: {=IFERROR(IF(SUMPRODUCT((INPUT!$M$3:$M$1000=$B$3+4)*(INPUT!$N$3:$N$1000="T")*(INPUT!$O$3:$O$1000="GARCIA"))=0,"",SUMPRODUCT((INPUT!$M$3:$M$1000=$B$3+4)*(INPUT!$N$3:$N$1000="T")*(INPUT!$O$3:$O$1000="GARCIA")*INPUT!$P$3:$P$1000)),"")} | Q9: {=IFERROR(IF(SUMPRODUCT((INPUT!$M$3:$M$1000=$B$3+4)*(INPUT!$N$3:$N$1000="T")*(INPUT!$O$3:$O$1000="GARCIA"))=0,"",SUMPRODUCT((INPUT!$M$3:$M$1000=$B$3+4)*(INPUT!$N$3:$N$1000="T")*(INPUT!$O$3:$O$1000="GARCIA")*INPUT!$Q$3:$Q$1000)),"")} | R9: =IFERROR(IF(OR(P9="",Q9=""),"",P9-Q9),"") | S9: {=IFERROR(IF(SUMPRODUCT((INPUT!$M$3:$M$1000=$B$3+5)*(INPUT!$N$3:$N$1000="T")*(INPUT!$O$3:$O$1000="GARCIA"))=0,"",SUMPRODUCT((INPUT!$M$3:$M$1000=$B$3+5)*(INPUT!$N$3:$N$1000="T")*(INPUT!$O$3:$O$1000="GARCIA")*INPUT!$P$3:$P$1000)),"")} -> 79.6 | T9: {=IFERROR(IF(SUMPRODUCT((INPUT!$M$3:$M$1000=$B$3+5)*(INPUT!$N$3:$N$1000="T")*(INPUT!$O$3:$O$1000="GARCIA"))=0,"",SUMPRODUCT((INPUT!$M$3:$M$1000=$B$3+5)*(INPUT!$N$3:$N$1000="T")*(INPUT!$O$3:$O$1000="GARCIA")*INPUT!$Q$3:$Q$1000)),"")} -> 79.4 | U9: =IFERROR(IF(OR(S9="",T9=""),"",S9-T9),"") -> 0.2 | V9: {=IFERROR(IF(SUMPRODUCT((INPUT!$M$3:$M$1000=$B$3+6)*(INPUT!$N$3:$N$1000="T")*(INPUT!$O$3:$O$1000="GARCIA"))=0,"",SUMPRODUCT((INPUT!$M$3:$M$1000=$B$3+6)*(INPUT!$N$3:$N$1000="T")*(INPUT!$O$3:$O$1000="GARCIA")*INPUT!$P$3:$P$1000)),"")} | W9: {=IFERROR(IF(SUMPRODUCT((INPUT!$M$3:$M$1000=$B$3+6)*(INPUT!$N$3:$N$1000="T")*(INPUT!$O$3:$O$1000="GARCIA"))=0,"",SUMPRODUCT((INPUT!$M$3:$M$1000=$B$3+6)*(INPUT!$N$3:$N$1000="T")*(INPUT!$O$3:$O$1000="GARCIA")*INPUT!$Q$3:$Q$1000)),"")} | X9: =IFERROR(IF(OR(V9="",W9=""),"",V9-W9),"")
A10: 3 | B10: OSCAR | C10: M | D10: {=IFERROR(IF(SUMPRODUCT((INPUT!$M$3:$M$1000=$B$3+0)*(INPUT!$N$3:$N$1000="M")*(INPUT!$O$3:$O$1000="OSCAR"))=0,"",SUMPRODUCT((INPUT!$M$3:$M$1000=$B$3+0)*(INPUT!$N$3:$N$1000="M")*(INPUT!$O$3:$O$1000="OSCAR")*INPUT!$P$3:$P$1000)),"")} | E10: {=IFERROR(IF(SUMPRODUCT((INPUT!$M$3:$M$1000=$B$3+0)*(INPUT!$N$3:$N$1000="M")*(INPUT!$O$3:$O$1000="OSCAR"))=0,"",SUMPRODUCT((INPUT!$M$3:$M$1000=$B$3+0)*(INPUT!$N$3:$N$1000="M")*(INPUT!$O$3:$O$1000="OSCAR")*INPUT!$Q$3:$Q$1000)),"")} | F10: =IFERROR(IF(OR(D10="",E10=""),"",D10-E10),"") | G10: {=IFERROR(IF(SUMPRODUCT((INPUT!$M$3:$M$1000=$B$3+1)*(INPUT!$N$3:$N$1000="M")*(INPUT!$O$3:$O$1000="OSCAR"))=0,"",SUMPRODUCT((INPUT!$M$3:$M$1000=$B$3+1)*(INPUT!$N$3:$N$1000="M")*(INPUT!$O$3:$O$1000="OSCAR")*INPUT!$P$3:$P$1000)),"")} -> 89 | H10: {=IFERROR(IF(SUMPRODUCT((INPUT!$M$3:$M$1000=$B$3+1)*(INPUT!$N$3:$N$1000="M")*(INPUT!$O$3:$O$1000="OSCAR"))=0,"",SUMPRODUCT((INPUT!$M$3:$M$1000=$B$3+1)*(INPUT!$N$3:$N$1000="M")*(INPUT!$O$3:$O$1000="OSCAR")*INPUT!$Q$3:$Q$1000)),"")} -> 87.4 | I10: =IFERROR(IF(OR(G10="",H10=""),"",G10-H10),"") -> 1.6 | J10: {=IFERROR(IF(SUMPRODUCT((INPUT!$M$3:$M$1000=$B$3+2)*(INPUT!$N$3:$N$1000="M")*(INPUT!$O$3:$O$1000="OSCAR"))=0,"",SUMPRODUCT((INPUT!$M$3:$M$1000=$B$3+2)*(INPUT!$N$3:$N$1000="M")*(INPUT!$O$3:$O$1000="OSCAR")*INPUT!$P$3:$P$1000)),"")} | K10: {=IFERROR(IF(SUMPRODUCT((INPUT!$M$3:$M$1000=$B$3+2)*(INPUT!$N$3:$N$1000="M")*(INPUT!$O$3:$O$1000="OSCAR"))=0,"",SUMPRODUCT((INPUT!$M$3:$M$1000=$B$3+2)*(INPUT!$N$3:$N$1000="M")*(INPUT!$O$3:$O$1000="OSCAR")*INPUT!$Q$3:$Q$1000)),"")} | L10: =IFERROR(IF(OR(J10="",K10=""),"",J10-K10),"") | M10: {=IFERROR(IF(SUMPRODUCT((INPUT!$M$3:$M$1000=$B$3+3)*(INPUT!$N$3:$N$1000="M")*(INPUT!$O$3:$O$1000="OSCAR"))=0,"",SUMPRODUCT((INPUT!$M$3:$M$1000=$B$3+3)*(INPUT!$N$3:$N$1000="M")*(INPUT!$O$3:$O$1000="OSCAR")*INPUT!$P$3:$P$1000)),"")} | N10: {=IFERROR(IF(SUMPRODUCT((INPUT!$M$3:$M$1000=$B$3+3)*(INPUT!$N$3:$N$1000="M")*(INPUT!$O$3:$O$1000="OSCAR"))=0,"",SUMPRODUCT((INPUT!$M$3:$M$1000=$B$3+3)*(INPUT!$N$3:$N$1000="M")*(INPUT!$O$3:$O$1000="OSCAR")*INPUT!$Q$3:$Q$1000)),"")} | O10: =IFERROR(IF(OR(M10="",N10=""),"",M10-N10),"") | P10: {=IFERROR(IF(SUMPRODUCT((INPUT!$M$3:$M$1000=$B$3+4)*(INPUT!$N$3:$N$1000="M")*(INPUT!$O$3:$O$1000="OSCAR"))=0,"",SUMPRODUCT((INPUT!$M$3:$M$1000=$B$3+4)*(INPUT!$N$3:$N$1000="M")*(INPUT!$O$3:$O$1000="OSCAR")*INPUT!$P$3:$P$1000)),"")} | Q10: {=IFERROR(IF(SUMPRODUCT((INPUT!$M$3:$M$1000=$B$3+4)*(INPUT!$N$3:$N$1000="M")*(INPUT!$O$3:$O$1000="OSCAR"))=0,"",SUMPRODUCT((INPUT!$M$3:$M$1000=$B$3+4)*(INPUT!$N$3:$N$1000="M")*(INPUT!$O$3:$O$1000="OSCAR")*INPUT!$Q$3:$Q$1000)),"")} | R10: =IFERROR(IF(OR(P10="",Q10=""),"",P10-Q10),"") | S10: {=IFERROR(IF(SUMPRODUCT((INPUT!$M$3:$M$1000=$B$3+5)*(INPUT!$N$3:$N$1000="M")*(INPUT!$O$3:$O$1000="OSCAR"))=0,"",SUMPRODUCT((INPUT!$M$3:$M$1000=$B$3+5)*(INPUT!$N$3:$N$1000="M")*(INPUT!$O$3:$O$1000="OSCAR")*INPUT!$P$3:$P$1000)),"")} | T10: {=IFERROR(IF(SUMPRODUCT((INPUT!$M$3:$M$1000=$B$3+5)*(INPUT!$N$3:$N$1000="M")*(INPUT!$O$3:$O$1000="OSCAR"))=0,"",SUMPRODUCT((INPUT!$M$3:$M$1000=$B$3+5)*(INPUT!$N$3:$N$1000="M")*(INPUT!$O$3:$O$1000="OSCAR")*INPUT!$Q$3:$Q$1000)),"")} | U10: =IFERROR(IF(OR(S10="",T10=""),"",S10-T10),"") | V10: {=IFERROR(IF(SUMPRODUCT((INPUT!$M$3:$M$1000=$B$3+6)*(INPUT!$N$3:$N$1000="M")*(INPUT!$O$3:$O$1000="OSCAR"))=0,"",SUMPRODUCT((INPUT!$M$3:$M$1000=$B$3+6)*(INPUT!$N$3:$N$1000="M")*(INPUT!$O$3:$O$1000="OSCAR")*INPUT!$P$3:$P$1000)),"")} | W10: {=IFERROR(IF(SUMPRODUCT((INPUT!$M$3:$M$1000=$B$3+6)*(INPUT!$N$3:$N$1000="M")*(INPUT!$O$3:$O$1000="OSCAR"))=0,"",SUMPRODUCT((INPUT!$M$3:$M$1000=$B$3+6)*(INPUT!$N$3:$N$1000="M")*(INPUT!$O$3:$O$1000="OSCAR")*INPUT!$Q$3:$Q$1000)),"")} | X10: =IFERROR(IF(OR(V10="",W10=""),"",V10-W10),"")
C11: T | D11: {=IFERROR(IF(SUMPRODUCT((INPUT!$M$3:$M$1000=$B$3+0)*(INPUT!$N$3:$N$1000="T")*(INPUT!$O$3:$O$1000="OSCAR"))=0,"",SUMPRODUCT((INPUT!$M$3:$M$1000=$B$3+0)*(INPUT!$N$3:$N$1000="T")*(INPUT!$O$3:$O$1000="OSCAR")*INPUT!$P$3:$P$1000)),"")} | E11: {=IFERROR(IF(SUMPRODUCT((INPUT!$M$3:$M$1000=$B$3+0)*(INPUT!$N$3:$N$1000="T")*(INPUT!$O$3:$O$1000="OSCAR"))=0,"",SUMPRODUCT((INPUT!$M$3:$M$1000=$B$3+0)*(INPUT!$N$3:$N$1000="T")*(INPUT!$O$3:$O$1000="OSCAR")*INPUT!$Q$3:$Q$1000)),"")} | F11: =IFERROR(IF(OR(D11="",E11=""),"",D11-E11),"") | G11: {=IFERROR(IF(SUMPRODUCT((INPUT!$M$3:$M$1000=$B$3+1)*(INPUT!$N$3:$N$1000="T")*(INPUT!$O$3:$O$1000="OSCAR"))=0,"",SUMPRODUCT((INPUT!$M$3:$M$1000=$B$3+1)*(INPUT!$N$3:$N$1000="T")*(INPUT!$O$3:$O$1000="OSCAR")*INPUT!$P$3:$P$1000)),"")} | H11: {=IFERROR(IF(SUMPRODUCT((INPUT!$M$3:$M$1000=$B$3+1)*(INPUT!$N$3:$N$1000="T")*(INPUT!$O$3:$O$1000="OSCAR"))=0,"",SUMPRODUCT((INPUT!$M$3:$M$1000=$B$3+1)*(INPUT!$N$3:$N$1000="T")*(INPUT!$O$3:$O$1000="OSCAR")*INPUT!$Q$3:$Q$1000)),"")} | I11: =IFERROR(IF(OR(G11="",H11=""),"",G11-H11),"") | J11: {=IFERROR(IF(SUMPRODUCT((INPUT!$M$3:$M$1000=$B$3+2)*(INPUT!$N$3:$N$1000="T")*(INPUT!$O$3:$O$1000="OSCAR"))=0,"",SUMPRODUCT((INPUT!$M$3:$M$1000=$B$3+2)*(INPUT!$N$3:$N$1000="T")*(INPUT!$O$3:$O$1000="OSCAR")*INPUT!$P$3:$P$1000)),"")} | K11: {=IFERROR(IF(SUMPRODUCT((INPUT!$M$3:$M$1000=$B$3+2)*(INPUT!$N$3:$N$1000="T")*(INPUT!$O$3:$O$1000="OSCAR"))=0,"",SUMPRODUCT((INPUT!$M$3:$M$1000=$B$3+2)*(INPUT!$N$3:$N$1000="T")*(INPUT!$O$3:$O$1000="OSCAR")*INPUT!$Q$3:$Q$1000)),"")} | L11: =IFERROR(IF(OR(J11="",K11=""),"",J11-K11),"") | M11: {=IFERROR(IF(SUMPRODUCT((INPUT!$M$3:$M$1000=$B$3+3)*(INPUT!$N$3:$N$1000="T")*(INPUT!$O$3:$O$1000="OSCAR"))=0,"",SUMPRODUCT((INPUT!$M$3:$M$1000=$B$3+3)*(INPUT!$N$3:$N$1000="T")*(INPUT!$O$3:$O$1000="OSCAR")*INPUT!$P$3:$P$1000)),"")} | N11: {=IFERROR(IF(SUMPRODUCT((INPUT!$M$3:$M$1000=$B$3+3)*(INPUT!$N$3:$N$1000="T")*(INPUT!$O$3:$O$1000="OSCAR"))=0,"",SUMPRODUCT((INPUT!$M$3:$M$1000=$B$3+3)*(INPUT!$N$3:$N$1000="T")*(INPUT!$O$3:$O$1000="OSCAR")*INPUT!$Q$3:$Q$1000)),"")} | O11: =IFERROR(IF(OR(M11="",N11=""),"",M11-N11),"") | P11: {=IFERROR(IF(SUMPRODUCT((INPUT!$M$3:$M$1000=$B$3+4)*(INPUT!$N$3:$N$1000="T")*(INPUT!$O$3:$O$1000="OSCAR"))=0,"",SUMPRODUCT((INPUT!$M$3:$M$1000=$B$3+4)*(INPUT!$N$3:$N$1000="T")*(INPUT!$O$3:$O$1000="OSCAR")*INPUT!$P$3:$P$1000)),"")} | Q11: {=IFERROR(IF(SUMPRODUCT((INPUT!$M$3:$M$1000=$B$3+4)*(INPUT!$N$3:$N$1000="T")*(INPUT!$O$3:$O$1000="OSCAR"))=0,"",SUMPRODUCT((INPUT!$M$3:$M$1000=$B$3+4)*(INPUT!$N$3:$N$1000="T")*(INPUT!$O$3:$O$1000="OSCAR")*INPUT!$Q$3:$Q$1000)),"")} | R11: =IFERROR(IF(OR(P11="",Q11=""),"",P11-Q11),"") | S11: {=IFERROR(IF(SUMPRODUCT((INPUT!$M$3:$M$1000=$B$3+5)*(INPUT!$N$3:$N$1000="T")*(INPUT!$O$3:$O$1000="OSCAR"))=0,"",SUMPRODUCT((INPUT!$M$3:$M$1000=$B$3+5)*(INPUT!$N$3:$N$1000="T")*(INPUT!$O$3:$O$1000="OSCAR")*INPUT!$P$3:$P$1000)),"")} | T11: {=IFERROR(IF(SUMPRODUCT((INPUT!$M$3:$M$1000=$B$3+5)*(INPUT!$N$3:$N$1000="T")*(INPUT!$O$3:$O$1000="OSCAR"))=0,"",SUMPRODUCT((INPUT!$M$3:$M$1000=$B$3+5)*(INPUT!$N$3:$N$1000="T")*(INPUT!$O$3:$O$1000="OSCAR")*INPUT!$Q$3:$Q$1000)),"")} | U11: =IFERROR(IF(OR(S11="",T11=""),"",S11-T11),"") | V11: {=IFERROR(IF(SUMPRODUCT((INPUT!$M$3:$M$1000=$B$3+6)*(INPUT!$N$3:$N$1000="T")*(INPUT!$O$3:$O$1000="OSCAR"))=0,"",SUMPRODUCT((INPUT!$M$3:$M$1000=$B$3+6)*(INPUT!$N$3:$N$1000="T")*(INPUT!$O$3:$O$1000="OSCAR")*INPUT!$P$3:$P$1000)),"")} | W11: {=IFERROR(IF(SUMPRODUCT((INPUT!$M$3:$M$1000=$B$3+6)*(INPUT!$N$3:$N$1000="T")*(INPUT!$O$3:$O$1000="OSCAR"))=0,"",SUMPRODUCT((INPUT!$M$3:$M$1000=$B$3+6)*(INPUT!$N$3:$N$1000="T")*(INPUT!$O$3:$O$1000="OSCAR")*INPUT!$Q$3:$Q$1000)),"")} | X11: =IFERROR(IF(OR(V11="",W11=""),"",V11-W11),"")
A12: 4 | B12: CECILIO | C12: M | D12: {=IFERROR(IF(SUMPRODUCT((INPUT!$M$3:$M$1000=$B$3+0)*(INPUT!$N$3:$N$1000="M")*(INPUT!$O$3:$O$1000="CECILIO"))=0,"",SUMPRODUCT((INPUT!$M$3:$M$1000=$B$3+0)*(INPUT!$N$3:$N$1000="M")*(INPUT!$O$3:$O$1000="CECILIO")*INPUT!$P$3:$P$1000)),"")} | E12: {=IFERROR(IF(SUMPRODUCT((INPUT!$M$3:$M$1000=$B$3+0)*(INPUT!$N$3:$N$1000="M")*(INPUT!$O$3:$O$1000="CECILIO"))=0,"",SUMPRODUCT((INPUT!$M$3:$M$1000=$B$3+0)*(INPUT!$N$3:$N$1000="M")*(INPUT!$O$3:$O$1000="CECILIO")*INPUT!$Q$3:$Q$1000)),"")} | F12: =IFERROR(IF(OR(D12="",E12=""),"",D12-E12),"") | G12: {=IFERROR(IF(SUMPRODUCT((INPUT!$M$3:$M$1000=$B$3+1)*(INPUT!$N$3:$N$1000="M")*(INPUT!$O$3:$O$1000="CECILIO"))=0,"",SUMPRODUCT((INPUT!$M$3:$M$1000=$B$3+1)*(INPUT!$N$3:$N$1000="M")*(INPUT!$O$3:$O$1000="CECILIO")*INPUT!$P$3:$P$1000)),"")} -> 68.2 | H12: {=IFERROR(IF(SUMPRODUCT((INPUT!$M$3:$M$1000=$B$3+1)*(INPUT!$N$3:$N$1000="M")*(INPUT!$O$3:$O$1000="CECILIO"))=0,"",SUMPRODUCT((INPUT!$M$3:$M$1000=$B$3+1)*(INPUT!$N$3:$N$1000="M")*(INPUT!$O$3:$O$1000="CECILIO")*INPUT!$Q$3:$Q$1000)),"")} -> 67.8 | I12: =IFERROR(IF(OR(G12="",H12=""),"",G12-H12),"") -> 0.4 | J12: {=IFERROR(IF(SUMPRODUCT((INPUT!$M$3:$M$1000=$B$3+2)*(INPUT!$N$3:$N$1000="M")*(INPUT!$O$3:$O$1000="CECILIO"))=0,"",SUMPRODUCT((INPUT!$M$3:$M$1000=$B$3+2)*(INPUT!$N$3:$N$1000="M")*(INPUT!$O$3:$O$1000="CECILIO")*INPUT!$P$3:$P$1000)),"")} -> 68 | K12: {=IFERROR(IF(SUMPRODUCT((INPUT!$M$3:$M$1000=$B$3+2)*(INPUT!$N$3:$N$1000="M")*(INPUT!$O$3:$O$1000="CECILIO"))=0,"",SUMPRODUCT((INPUT!$M$3:$M$1000=$B$3+2)*(INPUT!$N$3:$N$1000="M")*(INPUT!$O$3:$O$1000="CECILIO")*INPUT!$Q$3:$Q$1000)),"")} -> 67.2 | L12: =IFERROR(IF(OR(J12="",K12=""),"",J12-K12),"") -> 0.8 | M12: {=IFERROR(IF(SUMPRODUCT((INPUT!$M$3:$M$1000=$B$3+3)*(INPUT!$N$3:$N$1000="M")*(INPUT!$O$3:$O$1000="CECILIO"))=0,"",SUMPRODUCT((INPUT!$M$3:$M$1000=$B$3+3)*(INPUT!$N$3:$N$1000="M")*(INPUT!$O$3:$O$1000="CECILIO")*INPUT!$P$3:$P$1000)),"")} -> 68 | N12: {=IFERROR(IF(SUMPRODUCT((INPUT!$M$3:$M$1000=$B$3+3)*(INPUT!$N$3:$N$1000="M")*(INPUT!$O$3:$O$1000="CECILIO"))=0,"",SUMPRODUCT((INPUT!$M$3:$M$1000=$B$3+3)*(INPUT!$N$3:$N$1000="M")*(INPUT!$O$3:$O$1000="CECILIO")*INPUT!$Q$3:$Q$1000)),"")} -> 67.2 | O12: =IFERROR(IF(OR(M12="",N12=""),"",M12-N12),"") -> 0.8 | P12: {=IFERROR(IF(SUMPRODUCT((INPUT!$M$3:$M$1000=$B$3+4)*(INPUT!$N$3:$N$1000="M")*(INPUT!$O$3:$O$1000="CECILIO"))=0,"",SUMPRODUCT((INPUT!$M$3:$M$1000=$B$3+4)*(INPUT!$N$3:$N$1000="M")*(INPUT!$O$3:$O$1000="CECILIO")*INPUT!$P$3:$P$1000)),"")} -> 68.5 | Q12: {=IFERROR(IF(SUMPRODUCT((INPUT!$M$3:$M$1000=$B$3+4)*(INPUT!$N$3:$N$1000="M")*(INPUT!$O$3:$O$1000="CECILIO"))=0,"",SUMPRODUCT((INPUT!$M$3:$M$1000=$B$3+4)*(INPUT!$N$3:$N$1000="M")*(INPUT!$O$3:$O$1000="CECILIO")*INPUT!$Q$3:$Q$1000)),"")} -> 68.1 | R12: =IFERROR(IF(OR(P12="",Q12=""),"",P12-Q12),"") -> 0.4 | S12: {=IFERROR(IF(SUMPRODUCT((INPUT!$M$3:$M$1000=$B$3+5)*(INPUT!$N$3:$N$1000="M")*(INPUT!$O$3:$O$1000="CECILIO"))=0,"",SUMPRODUCT((INPUT!$M$3:$M$1000=$B$3+5)*(INPUT!$N$3:$N$1000="M")*(INPUT!$O$3:$O$1000="CECILIO")*INPUT!$P$3:$P$1000)),"")} | T12: {=IFERROR(IF(SUMPRODUCT((INPUT!$M$3:$M$1000=$B$3+5)*(INPUT!$N$3:$N$1000="M")*(INPUT!$O$3:$O$1000="CECILIO"))=0,"",SUMPRODUCT((INPUT!$M$3:$M$1000=$B$3+5)*(INPUT!$N$3:$N$1000="M")*(INPUT!$O$3:$O$1000="CECILIO")*INPUT!$Q$3:$Q$1000)),"")} | U12: =IFERROR(IF(OR(S12="",T12=""),"",S12-T12),"") | V12: {=IFERROR(IF(SUMPRODUCT((INPUT!$M$3:$M$1000=$B$3+6)*(INPUT!$N$3:$N$1000="M")*(INPUT!$O$3:$O$1000="CECILIO"))=0,"",SUMPRODUCT((INPUT!$M$3:$M$1000=$B$3+6)*(INPUT!$N$3:$N$1000="M")*(INPUT!$O$3:$O$1000="CECILIO")*INPUT!$P$3:$P$1000)),"")} | W12: {=IFERROR(IF(SUMPRODUCT((INPUT!$M$3:$M$1000=$B$3+6)*(INPUT!$N$3:$N$1000="M")*(INPUT!$O$3:$O$1000="CECILIO"))=0,"",SUMPRODUCT((INPUT!$M$3:$M$1000=$B$3+6)*(INPUT!$N$3:$N$1000="M")*(INPUT!$O$3:$O$1000="CECILIO")*INPUT!$Q$3:$Q$1000)),"")} | X12: =IFERROR(IF(OR(V12="",W12=""),"",V12-W12),"")
C13: T | D13: {=IFERROR(IF(SUMPRODUCT((INPUT!$M$3:$M$1000=$B$3+0)*(INPUT!$N$3:$N$1000="T")*(INPUT!$O$3:$O$1000="CECILIO"))=0,"",SUMPRODUCT((INPUT!$M$3:$M$1000=$B$3+0)*(INPUT!$N$3:$N$1000="T")*(INPUT!$O$3:$O$1000="CECILIO")*INPUT!$P$3:$P$1000)),"")} | E13: {=IFERROR(IF(SUMPRODUCT((INPUT!$M$3:$M$1000=$B$3+0)*(INPUT!$N$3:$N$1000="T")*(INPUT!$O$3:$O$1000="CECILIO"))=0,"",SUMPRODUCT((INPUT!$M$3:$M$1000=$B$3+0)*(INPUT!$N$3:$N$1000="T")*(INPUT!$O$3:$O$1000="CECILIO")*INPUT!$Q$3:$Q$1000)),"")} | F13: =IFERROR(IF(OR(D13="",E13=""),"",D13-E13),"") | G13: {=IFERROR(IF(SUMPRODUCT((INPUT!$M$3:$M$1000=$B$3+1)*(INPUT!$N$3:$N$1000="T")*(INPUT!$O$3:$O$1000="CECILIO"))=0,"",SUMPRODUCT((INPUT!$M$3:$M$1000=$B$3+1)*(INPUT!$N$3:$N$1000="T")*(INPUT!$O$3:$O$1000="CECILIO")*INPUT!$P$3:$P$1000)),"")} | H13: {=IFERROR(IF(SUMPRODUCT((INPUT!$M$3:$M$1000=$B$3+1)*(INPUT!$N$3:$N$1000="T")*(INPUT!$O$3:$O$1000="CECILIO"))=0,"",SUMPRODUCT((INPUT!$M$3:$M$1000=$B$3+1)*(INPUT!$N$3:$N$1000="T")*(INPUT!$O$3:$O$1000="CECILIO")*INPUT!$Q$3:$Q$1000)),"")} | I13: =IFERROR(IF(OR(G13="",H13=""),"",G13-H13),"") | J13: {=IFERROR(IF(SUMPRODUCT((INPUT!$M$3:$M$1000=$B$3+2)*(INPUT!$N$3:$N$1000="T")*(INPUT!$O$3:$O$1000="CECILIO"))=0,"",SUMPRODUCT((INPUT!$M$3:$M$1000=$B$3+2)*(INPUT!$N$3:$N$1000="T")*(INPUT!$O$3:$O$1000="CECILIO")*INPUT!$P$3:$P$1000)),"")} | K13: {=IFERROR(IF(SUMPRODUCT((INPUT!$M$3:$M$1000=$B$3+2)*(INPUT!$N$3:$N$1000="T")*(INPUT!$O$3:$O$1000="CECILIO"))=0,"",SUMPRODUCT((INPUT!$M$3:$M$1000=$B$3+2)*(INPUT!$N$3:$N$1000="T")*(INPUT!$O$3:$O$1000="CECILIO")*INPUT!$Q$3:$Q$1000)),"")} | L13: =IFERROR(IF(OR(J13="",K13=""),"",J13-K13),"") | M13: {=IFERROR(IF(SUMPRODUCT((INPUT!$M$3:$M$1000=$B$3+3)*(INPUT!$N$3:$N$1000="T")*(INPUT!$O$3:$O$1000="CECILIO"))=0,"",SUMPRODUCT((INPUT!$M$3:$M$1000=$B$3+3)*(INPUT!$N$3:$N$1000="T")*(INPUT!$O$3:$O$1000="CECILIO")*INPUT!$P$3:$P$1000)),"")} | N13: {=IFERROR(IF(SUMPRODUCT((INPUT!$M$3:$M$1000=$B$3+3)*(INPUT!$N$3:$N$1000="T")*(INPUT!$O$3:$O$1000="CECILIO"))=0,"",SUMPRODUCT((INPUT!$M$3:$M$1000=$B$3+3)*(INPUT!$N$3:$N$1000="T")*(INPUT!$O$3:$O$1000="CECILIO")*INPUT!$Q$3:$Q$1000)),"")} | O13: =IFERROR(IF(OR(M13="",N13=""),"",M13-N13),"") | P13: {=IFERROR(IF(SUMPRODUCT((INPUT!$M$3:$M$1000=$B$3+4)*(INPUT!$N$3:$N$1000="T")*(INPUT!$O$3:$O$1000="CECILIO"))=0,"",SUMPRODUCT((INPUT!$M$3:$M$1000=$B$3+4)*(INPUT!$N$3:$N$1000="T")*(INPUT!$O$3:$O$1000="CECILIO")*INPUT!$P$3:$P$1000)),"")} | Q13: {=IFERROR(IF(SUMPRODUCT((INPUT!$M$3:$M$1000=$B$3+4)*(INPUT!$N$3:$N$1000="T")*(INPUT!$O$3:$O$1000="CECILIO"))=0,"",SUMPRODUCT((INPUT!$M$3:$M$1000=$B$3+4)*(INPUT!$N$3:$N$1000="T")*(INPUT!$O$3:$O$1000="CECILIO")*INPUT!$Q$3:$Q$1000)),"")} | R13: =IFERROR(IF(OR(P13="",Q13=""),"",P13-Q13),"") | S13: {=IFERROR(IF(SUMPRODUCT((INPUT!$M$3:$M$1000=$B$3+5)*(INPUT!$N$3:$N$1000="T")*(INPUT!$O$3:$O$1000="CECILIO"))=0,"",SUMPRODUCT((INPUT!$M$3:$M$1000=$B$3+5)*(INPUT!$N$3:$N$1000="T")*(INPUT!$O$3:$O$1000="CECILIO")*INPUT!$P$3:$P$1000)),"")} -> 68 | T13: {=IFERROR(IF(SUMPRODUCT((INPUT!$M$3:$M$1000=$B$3+5)*(INPUT!$N$3:$N$1000="T")*(INPUT!$O$3:$O$1000="CECILIO"))=0,"",SUMPRODUCT((INPUT!$M$3:$M$1000=$B$3+5)*(INPUT!$N$3:$N$1000="T")*(INPUT!$O$3:$O$1000="CECILIO")*INPUT!$Q$3:$Q$1000)),"")} -> 67 | U13: =IFERROR(IF(OR(S13="",T13=""),"",S13-T13),"") -> 1 | V13: {=IFERROR(IF(SUMPRODUCT((INPUT!$M$3:$M$1000=$B$3+6)*(INPUT!$N$3:$N$1000="T")*(INPUT!$O$3:$O$1000="CECILIO"))=0,"",SUMPRODUCT((INPUT!$M$3:$M$1000=$B$3+6)*(INPUT!$N$3:$N$1000="T")*(INPUT!$O$3:$O$1000="CECILIO")*INPUT!$P$3:$P$1000)),"")} | W13: {=IFERROR(IF(SUMPRODUCT((INPUT!$M$3:$M$1000=$B$3+6)*(INPUT!$N$3:$N$1000="T")*(INPUT!$O$3:$O$1000="CECILIO"))=0,"",SUMPRODUCT((INPUT!$M$3:$M$1000=$B$3+6)*(INPUT!$N$3:$N$1000="T")*(INPUT!$O$3:$O$1000="CECILIO")*INPUT!$Q$3:$Q$1000)),"")} | X13: =IFERROR(IF(OR(V13="",W13=""),"",V13-W13),"")
A14: 5 | B14: CHAGUINHA | C14: M | D14: {=IFERROR(IF(SUMPRODUCT((INPUT!$M$3:$M$1000=$B$3+0)*(INPUT!$N$3:$N$1000="M")*(INPUT!$O$3:$O$1000="CHAGUINHA"))=0,"",SUMPRODUCT((INPUT!$M$3:$M$1000=$B$3+0)*(INPUT!$N$3:$N$1000="M")*(INPUT!$O$3:$O$1000="CHAGUINHA")*INPUT!$P$3:$P$1000)),"")} | E14: {=IFERROR(IF(SUMPRODUCT((INPUT!$M$3:$M$1000=$B$3+0)*(INPUT!$N$3:$N$1000="M")*(INPUT!$O$3:$O$1000="CHAGUINHA"))=0,"",SUMPRODUCT((INPUT!$M$3:$M$1000=$B$3+0)*(INPUT!$N$3:$N$1000="M")*(INPUT!$O$3:$O$1000="CHAGUINHA")*INPUT!$Q$3:$Q$1000)),"")} | F14: =IFERROR(IF(OR(D14="",E14=""),"",D14-E14),"") | G14: {=IFERROR(IF(SUMPRODUCT((INPUT!$M$3:$M$1000=$B$3+1)*(INPUT!$N$3:$N$1000="M")*(INPUT!$O$3:$O$1000="CHAGUINHA"))=0,"",SUMPRODUCT((INPUT!$M$3:$M$1000=$B$3+1)*(INPUT!$N$3:$N$1000="M")*(INPUT!$O$3:$O$1000="CHAGUINHA")*INPUT!$P$3:$P$1000)),"")} -> 69.3 | H14: {=IFERROR(IF(SUMPRODUCT((INPUT!$M$3:$M$1000=$B$3+1)*(INPUT!$N$3:$N$1000="M")*(INPUT!$O$3:$O$1000="CHAGUINHA"))=0,"",SUMPRODUCT((INPUT!$M$3:$M$1000=$B$3+1)*(INPUT!$N$3:$N$1000="M")*(INPUT!$O$3:$O$1000="CHAGUINHA")*INPUT!$Q$3:$Q$1000)),"")} -> 68.5 | I14: =IFERROR(IF(OR(G14="",H14=""),"",G14-H14),"") -> 0.8 | J14: {=IFERROR(IF(SUMPRODUCT((INPUT!$M$3:$M$1000=$B$3+2)*(INPUT!$N$3:$N$1000="M")*(INPUT!$O$3:$O$1000="CHAGUINHA"))=0,"",SUMPRODUCT((INPUT!$M$3:$M$1000=$B$3+2)*(INPUT!$N$3:$N$1000="M")*(INPUT!$O$3:$O$1000="CHAGUINHA")*INPUT!$P$3:$P$1000)),"")} -> 69 | K14: {=IFERROR(IF(SUMPRODUCT((INPUT!$M$3:$M$1000=$B$3+2)*(INPUT!$N$3:$N$1000="M")*(INPUT!$O$3:$O$1000="CHAGUINHA"))=0,"",SUMPRODUCT((INPUT!$M$3:$M$1000=$B$3+2)*(INPUT!$N$3:$N$1000="M")*(INPUT!$O$3:$O$1000="CHAGUINHA")*INPUT!$Q$3:$Q$1000)),"")} -> 68.6 | L14: =IFERROR(IF(OR(J14="",K14=""),"",J14-K14),"") -> 0.4 | M14: {=IFERROR(IF(SUMPRODUCT((INPUT!$M$3:$M$1000=$B$3+3)*(INPUT!$N$3:$N$1000="M")*(INPUT!$O$3:$O$1000="CHAGUINHA"))=0,"",SUMPRODUCT((INPUT!$M$3:$M$1000=$B$3+3)*(INPUT!$N$3:$N$1000="M")*(INPUT!$O$3:$O$1000="CHAGUINHA")*INPUT!$P$3:$P$1000)),"")} -> 69 | N14: {=IFERROR(IF(SUMPRODUCT((INPUT!$M$3:$M$1000=$B$3+3)*(INPUT!$N$3:$N$1000="M")*(INPUT!$O$3:$O$1000="CHAGUINHA"))=0,"",SUMPRODUCT((INPUT!$M$3:$M$1000=$B$3+3)*(INPUT!$N$3:$N$1000="M")*(INPUT!$O$3:$O$1000="CHAGUINHA")*INPUT!$Q$3:$Q$1000)),"")} -> 68.6 | O14: =IFERROR(IF(OR(M14="",N14=""),"",M14-N14),"") -> 0.4 | P14: {=IFERROR(IF(SUMPRODUCT((INPUT!$M$3:$M$1000=$B$3+4)*(INPUT!$N$3:$N$1000="M")*(INPUT!$O$3:$O$1000="CHAGUINHA"))=0,"",SUMPRODUCT((INPUT!$M$3:$M$1000=$B$3+4)*(INPUT!$N$3:$N$1000="M")*(INPUT!$O$3:$O$1000="CHAGUINHA")*INPUT!$P$3:$P$1000)),"")} -> 69 | Q14: {=IFERROR(IF(SUMPRODUCT((INPUT!$M$3:$M$1000=$B$3+4)*(INPUT!$N$3:$N$1000="M")*(INPUT!$O$3:$O$1000="CHAGUINHA"))=0,"",SUMPRODUCT((INPUT!$M$3:$M$1000=$B$3+4)*(INPUT!$N$3:$N$1000="M")*(INPUT!$O$3:$O$1000="CHAGUINHA")*INPUT!$Q$3:$Q$1000)),"")} -> 68.8 | R14: =IFERROR(IF(OR(P14="",Q14=""),"",P14-Q14),"") -> 0.2 | S14: {=IFERROR(IF(SUMPRODUCT((INPUT!$M$3:$M$1000=$B$3+5)*(INPUT!$N$3:$N$1000="M")*(INPUT!$O$3:$O$1000="CHAGUINHA"))=0,"",SUMPRODUCT((INPUT!$M$3:$M$1000=$B$3+5)*(INPUT!$N$3:$N$1000="M")*(INPUT!$O$3:$O$1000="CHAGUINHA")*INPUT!$P$3:$P$1000)),"")} | T14: {=IFERROR(IF(SUMPRODUCT((INPUT!$M$3:$M$1000=$B$3+5)*(INPUT!$N$3:$N$1000="M")*(INPUT!$O$3:$O$1000="CHAGUINHA"))=0,"",SUMPRODUCT((INPUT!$M$3:$M$1000=$B$3+5)*(INPUT!$N$3:$N$1000="M")*(INPUT!$O$3:$O$1000="CHAGUINHA")*INPUT!$Q$3:$Q$1000)),"")} | U14: =IFERROR(IF(OR(S14="",T14=""),"",S14-T14),"") | V14: {=IFERROR(IF(SUMPRODUCT((INPUT!$M$3:$M$1000=$B$3+6)*(INPUT!$N$3:$N$1000="M")*(INPUT!$O$3:$O$1000="CHAGUINHA"))=0,"",SUMPRODUCT((INPUT!$M$3:$M$1000=$B$3+6)*(INPUT!$N$3:$N$1000="M")*(INPUT!$O$3:$O$1000="CHAGUINHA")*INPUT!$P$3:$P$1000)),"")} | W14: {=IFERROR(IF(SUMPRODUCT((INPUT!$M$3:$M$1000=$B$3+6)*(INPUT!$N$3:$N$1000="M")*(INPUT!$O$3:$O$1000="CHAGUINHA"))=0,"",SUMPRODUCT((INPUT!$M$3:$M$1000=$B$3+6)*(INPUT!$N$3:$N$1000="M")*(INPUT!$O$3:$O$1000="CHAGUINHA")*INPUT!$Q$3:$Q$1000)),"")} | X14: =IFERROR(IF(OR(V14="",W14=""),"",V14-W14),"")
C15: T | D15: {=IFERROR(IF(SUMPRODUCT((INPUT!$M$3:$M$1000=$B$3+0)*(INPUT!$N$3:$N$1000="T")*(INPUT!$O$3:$O$1000="CHAGUINHA"))=0,"",SUMPRODUCT((INPUT!$M$3:$M$1000=$B$3+0)*(INPUT!$N$3:$N$1000="T")*(INPUT!$O$3:$O$1000="CHAGUINHA")*INPUT!$P$3:$P$1000)),"")} | E15: {=IFERROR(IF(SUMPRODUCT((INPUT!$M$3:$M$1000=$B$3+0)*(INPUT!$N$3:$N$1000="T")*(INPUT!$O$3:$O$1000="CHAGUINHA"))=0,"",SUMPRODUCT((INPUT!$M$3:$M$1000=$B$3+0)*(INPUT!$N$3:$N$1000="T")*(INPUT!$O$3:$O$1000="CHAGUINHA")*INPUT!$Q$3:$Q$1000)),"")} | F15: =IFERROR(IF(OR(D15="",E15=""),"",D15-E15),"") | G15: {=IFERROR(IF(SUMPRODUCT((INPUT!$M$3:$M$1000=$B$3+1)*(INPUT!$N$3:$N$1000="T")*(INPUT!$O$3:$O$1000="CHAGUINHA"))=0,"",SUMPRODUCT((INPUT!$M$3:$M$1000=$B$3+1)*(INPUT!$N$3:$N$1000="T")*(INPUT!$O$3:$O$1000="CHAGUINHA")*INPUT!$P$3:$P$1000)),"")} | H15: {=IFERROR(IF(SUMPRODUCT((INPUT!$M$3:$M$1000=$B$3+1)*(INPUT!$N$3:$N$1000="T")*(INPUT!$O$3:$O$1000="CHAGUINHA"))=0,"",SUMPRODUCT((INPUT!$M$3:$M$1000=$B$3+1)*(INPUT!$N$3:$N$1000="T")*(INPUT!$O$3:$O$1000="CHAGUINHA")*INPUT!$Q$3:$Q$1000)),"")} | I15: =IFERROR(IF(OR(G15="",H15=""),"",G15-H15),"") | J15: {=IFERROR(IF(SUMPRODUCT((INPUT!$M$3:$M$1000=$B$3+2)*(INPUT!$N$3:$N$1000="T")*(INPUT!$O$3:$O$1000="CHAGUINHA"))=0,"",SUMPRODUCT((INPUT!$M$3:$M$1000=$B$3+2)*(INPUT!$N$3:$N$1000="T")*(INPUT!$O$3:$O$1000="CHAGUINHA")*INPUT!$P$3:$P$1000)),"")} | K15: {=IFERROR(IF(SUMPRODUCT((INPUT!$M$3:$M$1000=$B$3+2)*(INPUT!$N$3:$N$1000="T")*(INPUT!$O$3:$O$1000="CHAGUINHA"))=0,"",SUMPRODUCT((INPUT!$M$3:$M$1000=$B$3+2)*(INPUT!$N$3:$N$1000="T")*(INPUT!$O$3:$O$1000="CHAGUINHA")*INPUT!$Q$3:$Q$1000)),"")} | L15: =IFERROR(IF(OR(J15="",K15=""),"",J15-K15),"") | M15: {=IFERROR(IF(SUMPRODUCT((INPUT!$M$3:$M$1000=$B$3+3)*(INPUT!$N$3:$N$1000="T")*(INPUT!$O$3:$O$1000="CHAGUINHA"))=0,"",SUMPRODUCT((INPUT!$M$3:$M$1000=$B$3+3)*(INPUT!$N$3:$N$1000="T")*(INPUT!$O$3:$O$1000="CHAGUINHA")*INPUT!$P$3:$P$1000)),"")} | N15: {=IFERROR(IF(SUMPRODUCT((INPUT!$M$3:$M$1000=$B$3+3)*(INPUT!$N$3:$N$1000="T")*(INPUT!$O$3:$O$1000="CHAGUINHA"))=0,"",SUMPRODUCT((INPUT!$M$3:$M$1000=$B$3+3)*(INPUT!$N$3:$N$1000="T")*(INPUT!$O$3:$O$1000="CHAGUINHA")*INPUT!$Q$3:$Q$1000)),"")} | O15: =IFERROR(IF(OR(M15="",N15=""),"",M15-N15),"") | P15: {=IFERROR(IF(SUMPRODUCT((INPUT!$M$3:$M$1000=$B$3+4)*(INPUT!$N$3:$N$1000="T")*(INPUT!$O$3:$O$1000="CHAGUINHA"))=0,"",SUMPRODUCT((INPUT!$M$3:$M$1000=$B$3+4)*(INPUT!$N$3:$N$1000="T")*(INPUT!$O$3:$O$1000="CHAGUINHA")*INPUT!$P$3:$P$1000)),"")} | Q15: {=IFERROR(IF(SUMPRODUCT((INPUT!$M$3:$M$1000=$B$3+4)*(INPUT!$N$3:$N$1000="T")*(INPUT!$O$3:$O$1000="CHAGUINHA"))=0,"",SUMPRODUCT((INPUT!$M$3:$M$1000=$B$3+4)*(INPUT!$N$3:$N$1000="T")*(INPUT!$O$3:$O$1000="CHAGUINHA")*INPUT!$Q$3:$Q$1000)),"")} | R15: =IFERROR(IF(OR(P15="",Q15=""),"",P15-Q15),"") | S15: {=IFERROR(IF(SUMPRODUCT((INPUT!$M$3:$M$1000=$B$3+5)*(INPUT!$N$3:$N$1000="T")*(INPUT!$O$3:$O$1000="CHAGUINHA"))=0,"",SUMPRODUCT((INPUT!$M$3:$M$1000=$B$3+5)*(INPUT!$N$3:$N$1000="T")*(INPUT!$O$3:$O$1000="CHAGUINHA")*INPUT!$P$3:$P$1000)),"")} -> 69 | T15: {=IFERROR(IF(SUMPRODUCT((INPUT!$M$3:$M$1000=$B$3+5)*(INPUT!$N$3:$N$1000="T")*(INPUT!$O$3:$O$1000="CHAGUINHA"))=0,"",SUMPRODUCT((INPUT!$M$3:$M$1000=$B$3+5)*(INPUT!$N$3:$N$1000="T")*(INPUT!$O$3:$O$1000="CHAGUINHA")*INPUT!$Q$3:$Q$1000)),"")} -> 68 | U15: =IFERROR(IF(OR(S15="",T15=""),"",S15-T15),"") -> 1 | V15: {=IFERROR(IF(SUMPRODUCT((INPUT!$M$3:$M$1000=$B$3+6)*(INPUT!$N$3:$N$1000="T")*(INPUT!$O$3:$O$1000="CHAGUINHA"))=0,"",SUMPRODUCT((INPUT!$M$3:$M$1000=$B$3+6)*(INPUT!$N$3:$N$1000="T")*(INPUT!$O$3:$O$1000="CHAGUINHA")*INPUT!$P$3:$P$1000)),"")} | W15: {=IFERROR(IF(SUMPRODUCT((INPUT!$M$3:$M$1000=$B$3+6)*(INPUT!$N$3:$N$1000="T")*(INPUT!$O$3:$O$1000="CHAGUINHA"))=0,"",SUMPRODUCT((INPUT!$M$3:$M$1000=$B$3+6)*(INPUT!$N$3:$N$1000="T")*(INPUT!$O$3:$O$1000="CHAGUINHA")*INPUT!$Q$3:$Q$1000)),"")} | X15: =IFERROR(IF(OR(V15="",W15=""),"",V15-W15),"")
A16: 6 | B16: RAUL | C16: M | D16: {=IFERROR(IF(SUMPRODUCT((INPUT!$M$3:$M$1000=$B$3+0)*(INPUT!$N$3:$N$1000="M")*(INPUT!$O$3:$O$1000="RAUL"))=0,"",SUMPRODUCT((INPUT!$M$3:$M$1000=$B$3+0)*(INPUT!$N$3:$N$1000="M")*(INPUT!$O$3:$O$1000="RAUL")*INPUT!$P$3:$P$1000)),"")} | E16: {=IFERROR(IF(SUMPRODUCT((INPUT!$M$3:$M$1000=$B$3+0)*(INPUT!$N$3:$N$1000="M")*(INPUT!$O$3:$O$1000="RAUL"))=0,"",SUMPRODUCT((INPUT!$M$3:$M$1000=$B$3+0)*(INPUT!$N$3:$N$1000="M")*(INPUT!$O$3:$O$1000="RAUL")*INPUT!$Q$3:$Q$1000)),"")} | F16: =IFERROR(IF(OR(D16="",E16=""),"",D16-E16),"") | G16: {=IFERROR(IF(SUMPRODUCT((INPUT!$M$3:$M$1000=$B$3+1)*(INPUT!$N$3:$N$1000="M")*(INPUT!$O$3:$O$1000="RAUL"))=0,"",SUMPRODUCT((INPUT!$M$3:$M$1000=$B$3+1)*(INPUT!$N$3:$N$1000="M")*(INPUT!$O$3:$O$1000="RAUL")*INPUT!$P$3:$P$1000)),"")} -> 80 | H16: {=IFERROR(IF(SUMPRODUCT((INPUT!$M$3:$M$1000=$B$3+1)*(INPUT!$N$3:$N$1000="M")*(INPUT!$O$3:$O$1000="RAUL"))=0,"",SUMPRODUCT((INPUT!$M$3:$M$1000=$B$3+1)*(INPUT!$N$3:$N$1000="M")*(INPUT!$O$3:$O$1000="RAUL")*INPUT!$Q$3:$Q$1000)),"")} -> 80.1 | I16: =IFERROR(IF(OR(G16="",H16=""),"",G16-H16),"") -> -0.1 | J16: {=IFERROR(IF(SUMPRODUCT((INPUT!$M$3:$M$1000=$B$3+2)*(INPUT!$N$3:$N$1000="M")*(INPUT!$O$3:$O$1000="RAUL"))=0,"",SUMPRODUCT((INPUT!$M$3:$M$1000=$B$3+2)*(INPUT!$N$3:$N$1000="M")*(INPUT!$O$3:$O$1000="RAUL")*INPUT!$P$3:$P$1000)),"")} -> 80.6 | K16: {=IFERROR(IF(SUMPRODUCT((INPUT!$M$3:$M$1000=$B$3+2)*(INPUT!$N$3:$N$1000="M")*(INPUT!$O$3:$O$1000="RAUL"))=0,"",SUMPRODUCT((INPUT!$M$3:$M$1000=$B$3+2)*(INPUT!$N$3:$N$1000="M")*(INPUT!$O$3:$O$1000="RAUL")*INPUT!$Q$3:$Q$1000)),"")} -> 80.8 | L16: =IFERROR(IF(OR(J16="",K16=""),"",J16-K16),"") -> -0.2 | M16: {=IFERROR(IF(SUMPRODUCT((INPUT!$M$3:$M$1000=$B$3+3)*(INPUT!$N$3:$N$1000="M")*(INPUT!$O$3:$O$1000="RAUL"))=0,"",SUMPRODUCT((INPUT!$M$3:$M$1000=$B$3+3)*(INPUT!$N$3:$N$1000="M")*(INPUT!$O$3:$O$1000="RAUL")*INPUT!$P$3:$P$1000)),"")} -> 80.6 | N16: {=IFERROR(IF(SUMPRODUCT((INPUT!$M$3:$M$1000=$B$3+3)*(INPUT!$N$3:$N$1000="M")*(INPUT!$O$3:$O$1000="RAUL"))=0,"",SUMPRODUCT((INPUT!$M$3:$M$1000=$B$3+3)*(INPUT!$N$3:$N$1000="M")*(INPUT!$O$3:$O$1000="RAUL")*INPUT!$Q$3:$Q$1000)),"")} -> 80.8 | O16: =IFERROR(IF(OR(M16="",N16=""),"",M16-N16),"") -> -0.2 | P16: {=IFERROR(IF(SUMPRODUCT((INPUT!$M$3:$M$1000=$B$3+4)*(INPUT!$N$3:$N$1000="M")*(INPUT!$O$3:$O$1000="RAUL"))=0,"",SUMPRODUCT((INPUT!$M$3:$M$1000=$B$3+4)*(INPUT!$N$3:$N$1000="M")*(INPUT!$O$3:$O$1000="RAUL")*INPUT!$P$3:$P$1000)),"")} -> 80.3 | Q16: {=IFERROR(IF(SUMPRODUCT((INPUT!$M$3:$M$1000=$B$3+4)*(INPUT!$N$3:$N$1000="M")*(INPUT!$O$3:$O$1000="RAUL"))=0,"",SUMPRODUCT((INPUT!$M$3:$M$1000=$B$3+4)*(INPUT!$N$3:$N$1000="M")*(INPUT!$O$3:$O$1000="RAUL")*INPUT!$Q$3:$Q$1000)),"")} -> 79.8 | R16: =IFERROR(IF(OR(P16="",Q16=""),"",P16-Q16),"") -> 0.5 | S16: {=IFERROR(IF(SUMPRODUCT((INPUT!$M$3:$M$1000=$B$3+5)*(INPUT!$N$3:$N$1000="M")*(INPUT!$O$3:$O$1000="RAUL"))=0,"",SUMPRODUCT((INPUT!$M$3:$M$1000=$B$3+5)*(INPUT!$N$3:$N$1000="M")*(INPUT!$O$3:$O$1000="RAUL")*INPUT!$P$3:$P$1000)),"")} | T16: {=IFERROR(IF(SUMPRODUCT((INPUT!$M$3:$M$1000=$B$3+5)*(INPUT!$N$3:$N$1000="M")*(INPUT!$O$3:$O$1000="RAUL"))=0,"",SUMPRODUCT((INPUT!$M$3:$M$1000=$B$3+5)*(INPUT!$N$3:$N$1000="M")*(INPUT!$O$3:$O$1000="RAUL")*INPUT!$Q$3:$Q$1000)),"")} | U16: =IFERROR(IF(OR(S16="",T16=""),"",S16-T16),"") | V16: {=IFERROR(IF(SUMPRODUCT((INPUT!$M$3:$M$1000=$B$3+6)*(INPUT!$N$3:$N$1000="M")*(INPUT!$O$3:$O$1000="RAUL"))=0,"",SUMPRODUCT((INPUT!$M$3:$M$1000=$B$3+6)*(INPUT!$N$3:$N$1000="M")*(INPUT!$O$3:$O$1000="RAUL")*INPUT!$P$3:$P$1000)),"")} | W16: {=IFERROR(IF(SUMPRODUCT((INPUT!$M$3:$M$1000=$B$3+6)*(INPUT!$N$3:$N$1000="M")*(INPUT!$O$3:$O$1000="RAUL"))=0,"",SUMPRODUCT((INPUT!$M$3:$M$1000=$B$3+6)*(INPUT!$N$3:$N$1000="M")*(INPUT!$O$3:$O$1000="RAUL")*INPUT!$Q$3:$Q$1000)),"")} | X16: =IFERROR(IF(OR(V16="",W16=""),"",V16-W16),"")
